Workbook
Name \0: '[1]C-1'!$R$2
Name \t: '[2]ELEC45-01'!#REF!
Name ______tx1999: #REF!
Name ______tx2000: #REF!
Name _____ar2: #REF!
Name _____dkk1: #N/A
Name _____dkk2: #N/A
Name _____exp10: #N/A
Name _____exp11: #N/A
Name _____exp12: #N/A
Name _____EXP22: #N/A
Name _____exp5: #N/A
Name _____exp7: #N/A
Name _____exp8: #N/A
Name _____exp9: #N/A
Name _____lit1: #N/A
Name _____lit2: #N/A
Name _____Us1: #N/A
Name _____Us2: #N/A
Name _____Uss1: #N/A
Name _____Uss2: #N/A
Name ____ar2: #REF!
Name ____dkk1: #REF!
Name ____dkk2: #REF!
Name ____exp10: #REF!
Name ____exp11: #REF!
Name ____exp12: #REF!
Name ____EXP22: #REF!
Name ____exp5: #REF!
Name ____exp7: #REF!
Name ____exp8: #REF!
Name ____exp9: #REF!
Name ____lit1: #REF!
Name ____lit2: #REF!
Name ____tx1999: #REF!
Name ____tx2000: #REF!
Name ____Us1: #REF!
Name ____Us2: #REF!
Name ____Uss1: #REF!
Name ____Uss2: #REF!
Name ___SCB1: '[3]SCB 1 - Current'!$F$10
Name ___SCB2: '[3]SCB 2 - Current'!$F$11
Name ___tx1999: #REF!
Name ___tx2000: #REF!
Name __ar2: #REF!
Name __dkk1: #REF!
Name __dkk2: #REF!
Name __exp10: #REF!
Name __exp11: #REF!
Name __exp12: #REF!
Name __EXP22: #REF!
Name __exp5: #REF!
Name __exp7: #REF!
Name __exp8: #REF!
Name __exp9: #REF!
Name __lit1: #REF!
Name __lit2: #REF!
Name __SCB1: '[3]SCB 1 - Current'!$F$10
Name __SCB2: '[3]SCB 2 - Current'!$F$11
Name __tx1999: #REF!

Sheet 后勤部现状看板分析 
A1: 后勤部-架构及分析
A5: 序号 | B5: 姓名 | C5: 职务 | D5: 部门名称 | E5: 家乡 | F5: 学校 | G5: 专业 | H5: 学历 | I5: 学历类别 | J5: 院校类别 | K5: 性别 | L5: 年龄 | M5: 司龄/年 | N5: 司龄/月 | O5: 岗位级别 | P5: 岗位性质 | Q5: 到职日期 | R5: 出生日期 | S5: 备注
A6: 1 | B6: 李兵 | C6: 部长 | D6: 后勤部 | E6: 山西运城 | F6: 龙居中学 | G6: / | H6: 高中 | I6: / | J6: / | K6: 男 | L6: 37 | M6: =DATEDIF(Q6,DATE(2026,4,17),"Y") -> 4 | N6: =DATEDIF(Q6,DATE(2026,4,17),"YM") -> 8 | O6: 部长 | P6: 管理岗 | Q6: 44419 | R6: 32382
A7: 2 | B7: 曾嘉惠 | C7: 文控 | D7: 后勤部 | E7: 广东江门 | F7: 广东环境保护工程职业学院 | G7: 园林工程技术 | H7: 大专 | I7: 专科 | J7: 公办 | K7: 女 | L7: 25 | M7: =DATEDIF(Q7,DATE(2026,4,17),"Y") -> 4 | N7: =DATEDIF(Q7,DATE(2026,4,17),"YM") -> 2 | O7: 职能人员 | P7: 行政岗 | Q7: 44585 | R7: 36761
A8: 3 | B8: 沈云杰 | C8: 副主管 | D8: 安保处 | E8: 江苏泰州 | F8: 江苏农牧科技职业学院 | G8: 物流管理 | H8: 大专 | I8: 专科 | J8: 公办 | K8: 男 | L8: 31 | M8: =DATEDIF(Q8,DATE(2026,4,17),"Y") -> 0 | N8: =DATEDIF(Q8,DATE(2026,4,17),"YM") -> 11 | O8: 职能人员 | P8: 后勤岗 | Q8: 45770 | R8: 27492
A9: 4 | B9: 刘家华 | C9: 车辆停泊监察专员 | D9: 安保处 | E9: 广东韶关 | F9: 南雄中学 | G9: / | H9: 高中 | I9: / | J9: / | K9: 男 | L9: 43 | M9: =DATEDIF(Q9,DATE(2026,4,17),"Y") -> 4 | N9: =DATEDIF(Q9,DATE(2026,4,17),"YM") -> 8 | O9: 职能人员 | P9: 后勤岗 | Q9: 44419 | R9: 29214
A10: 5 | B10: 黄健波 | C10: 保安 | D10: 安保处 | E10: 广东江门 | F10: 江门市高级技工学校 | G10: 钳工数控 | H10: 中专 | I10: / | J10: 公办 | K10: 男 | L10: 37 | M10: =DATEDIF(Q10,DATE(2026,4,17),"Y") -> 3 | N10: =DATEDIF(Q10,DATE(2026,4,17),"YM") -> 9 | O10: 职能人员 | P10: 后勤岗 | Q10: 44736 | R10: 32971
A11: 6 | B11: 陶瑞麟 | C11: 保安 | D11: 安保处 | E11: 湖北谷城 | F11: 谷城县第三高级中学 | G11: / | H11: 高中 | I11: / | J11: / | K11: 男 | L11: 31 | M11: =DATEDIF(Q11,DATE(2026,4,17),"Y") -> 1 | N11: =DATEDIF(Q11,DATE(2026,4,17),"YM") -> 2 | O11: 职能人员 | P11: 后勤岗 | Q11: 45700 | R11: 29773
A12: 7 | B12: 唐银龙 | C12: 保安 | D12: 安保处 | E12: 四川宜宾 | F12: 江门技师学院 | G12: 营销与服装 | H12: 中专 | I12: / | J12: / | K12: 男 | L12: 28 | M12: =DATEDIF(Q12,DATE(2026,4,17),"Y") -> 1 | N12: =DATEDIF(Q12,DATE(2026,4,17),"YM") -> 1 | O12: 职能人员 | P12: 后勤岗 | Q12: 45715 | R12: 30125
A13: 8 | B13: 贺一文 | C13: 保安 | D13: 安保处 | E13: 湖南湘潭 | F13: 湘潭县一职 | G13: 计算机 | H13: 中专 | I13: / | J13: / | K13: 男 | L13: 31 | M13: =DATEDIF(Q13,DATE(2026,4,17),"Y") -> 1 | N13: =DATEDIF(Q13,DATE(2026,4,17),"YM") -> 5 | O13: 职能人员 | P13: 后勤岗 | Q13: 45603 | R13: 32042
A14: 9 | B14: 李俊岗 | C14: 保安 | D14: 安保处 | E14: 云南省红河哈尼 族彝族自治州弥勒市 | F14: 弥勒市第二中学 | G14: / | H14: 高中 | I14: / | J14: / | K14: 男 | L14: 26 | M14: =DATEDIF(Q14,DATE(2026,4,17),"Y") -> 0 | N14: =DATEDIF(Q14,DATE(2026,4,17),"YM") -> 11 | O14: 职能人员 | P14: 后勤岗 | Q14: 45770 | R14: 31021
A15: 10 | B15: 罗伟 | C15: 保安 | D15: 安保处 | E15: 贵州德江 | F15: 江门市技师学院 | G15: 烹饪（中式烹调） | H15: 中专 | I15: / | J15: / | K15: 男 | L15: 22 | M15: =DATEDIF(Q15,DATE(2026,4,17),"Y") -> 0 | N15: =DATEDIF(Q15,DATE(2026,4,17),"YM") -> 7 | O15: 职能人员 | P15: 后勤岗 | Q15: 45915 | R15: 30966
A16: 11 | B16: 邝凌鹏 | C16: 保安 | D16: 安保处 | E16: 广东乐昌 | F16: 韶关市振华中等职业学校 | G16: 汽车运用与维修 | H16: 中专 | I16: / | J16: / | K16: 男 | L16: 23 | M16: =DATEDIF(Q16,DATE(2026,4,17),"Y") -> 1 | N16: =DATEDIF(Q16,DATE(2026,4,17),"YM") -> 1 | O16: 职能人员 | P16: 后勤岗 | Q16: 45720 | R16: 29236
A17: 12 | B17: 职季魁 | C17: 保安 | D17: 安保处 | E17: 河南新乡 | F17: 获嘉县高级中学 | G17: / | H17: 高中 | I17: / | J17: / | K17: 男 | L17: 29 | M17: =DATEDIF(Q17,DATE(2026,4,17),"Y") -> 0 | N17: =DATEDIF(Q17,DATE(2026,4,17),"YM") -> 2 | O17: 职能人员 | P17: 后勤岗 | Q17: 46058 | R17: 35700
... A58: 53 | B58: 牛佳明 | C58: IT工程师 | D58: 综合项目管理处 | E58: 山西运城 | F58: 中北大学 | G58: 软件工程 | H58: 本科 | I58: 一本 | J58: 公办 | K58: 男 | L58: 23 | M58: =DATEDIF(Q58,DATE(2026,4,17),"Y") -> 0 | N58: =DATEDIF(Q58,DATE(2026,4,17),"YM") -> 0 | O58: 职能人员 | P58: 技术岗 | Q58: 46128 | R58: 37560
B61: 后勤部部门架构现状分析
B63: 学历水平分析 | F63: 年龄层结构分析
B64: 本科（985） | C64: 0 | D64: =C64/$C$70 -> 0 | F64: 20-25岁 | G64: =COUNTIFS(L6:L62,">=20",L6:L62,"<=25") -> 15 | H64: =G64/$G$69 -> 0.28301887
B65: 本科（211） | C65: 0 | D65: =C65/$C$70 -> 0 | F65: 26-30岁 | G65: =COUNTIFS(L6:L62,">=26",L6:L62,"<=30") -> 14 | H65: =G65/$G$69 -> 0.26415094
B66: 本科（一本） | C66: =COUNTIF(I6:I66,"一本") -> 3 | D66: =C66/$C$70 -> 0.056603774 | F66: 31-35岁 | G66: =COUNTIFS(L6:L62,">=31",L6:L62,"<=35") -> 6 | H66: =G66/$G$69 -> 0.11320755
B67: 本科（二本） | C67: =COUNTIF(I6:I66,"二本") -> 6 | D67: =C67/$C$70 -> 0.11320755 | F67: 36-40岁 | G67: =COUNTIFS(L6:L62,">=36",L6:L62,"<=40") -> 6 | H67: =G67/$G$69 -> 0.11320755
B68: 专科 | C68: =COUNTIF(I6:I66,"专科") -> 15 | D68: =C68/$C$70 -> 0.28301887 | F68: 40岁以上 | G68: =COUNTIFS(L6:L62,">=40") -> 12 | H68: =G68/$G$69 -> 0.22641509
B69: 其他 | C69: =COUNTIF(I6:I66,"/") -> 29 | D69: =C69/$C$70 -> 0.54716981 | F69: 合计 | G69: =SUM(G64:G68) -> 53 | H69: =G69/$G$69 -> 1
B70: 合计 | C70: =SUM(C64:C69) -> 53 | D70: =C70/$C$70 -> 1
F71: 司龄分析
B72: 男女比例分析 | F72: 平均年龄（岁） | H72: =AVERAGE(L6:L62) -> 31.981132
B73: 男 | C73: =COUNTIF(K6:K66,"男") -> 36 | D73: =C73/C75 -> 0.67924528 | F73: 最高年龄（岁） | H73: =MAX(L6:L62) -> 53
B74: 女 | C74: =COUNTIF(K6:K66,"女") -> 17 | D74: =C74/C75 -> 0.32075472 | F74: 平均司龄（年） | H74: =AVERAGE(M6:M62) -> 2.2264151
B75: 总计 | C75: =C73+C74 -> 53 | D75: =SUM(D73:D74) -> 1 | F75: 最高司龄（年） | H75: =MAX(M6:M62) -> 16

Sheet 2026人力资源规划
A1: 2026年人力资源规划
A2: 部门 | B2: 评价指标 | D2: 2026年目标 （举例） | E2: 1月 | F2: 2月 | G2: 3月 | H2: 4月 | I2: 5月 | J2: 6月 | K2: 7月 | L2: 8月 | M2: 9月 | N2: 10月 | O2: 11月 | P2: 12月
E3: 实际 | F3: 实际 | G3: 实际 | H3: 计划 | I3: 计划 | J3: 计划 | K3: 计划 | L3: 计划 | M3: 计划 | N3: 计划 | O3: 计划 | P3: 计划
A4: 后勤部 | B4: 编制 | C4: 在编 | D4: 48 | E4: {=SUM(COUNTIFS(人员调整计划!$E:$E,$A4,人员调整计划!BL:BL,{"在编","调岗","优化","新增"}))} -> 52 | F4: {=SUM(COUNTIFS(人员调整计划!$E:$E,$A4,人员调整计划!BM:BM,{"在编","调岗","优化","新增"}))} -> 52 | G4: {=SUM(COUNTIFS(人员调整计划!$E:$E,$A4,人员调整计划!BN:BN,{"在编","调岗","优化","新增"}))} -> 52 | H4: {=SUM(COUNTIFS(人员调整计划!$E:$E,$A4,人员调整计划!BO:BO,{"在编","调岗","优化","新增"}))} -> 57 | I4: {=SUM(COUNTIFS(人员调整计划!$E:$E,$A4,人员调整计划!BP:BP,{"在编","调岗","优化","新增"}))} -> 63 | J4: {=SUM(COUNTIFS(人员调整计划!$E:$E,$A4,人员调整计划!BQ:BQ,{"在编","调岗","优化","新增"}))} -> 59 | K4: {=SUM(COUNTIFS(人员调整计划!$E:$E,$A4,人员调整计划!BR:BR,{"在编","调岗","优化","新增"}))} -> 56 | L4: {=SUM(COUNTIFS(人员调整计划!$E:$E,$A4,人员调整计划!BS:BS,{"在编","调岗","优化","新增"}))} -> 48 | M4: {=SUM(COUNTIFS(人员调整计划!$E:$E,$A4,人员调整计划!BT:BT,{"在编","调岗","优化","新增"}))} -> 48 | N4: {=SUM(COUNTIFS(人员调整计划!$E:$E,$A4,人员调整计划!BU:BU,{"在编","调岗","优化","新增"}))} -> 48 | O4: {=SUM(COUNTIFS(人员调整计划!$E:$E,$A4,人员调整计划!BV:BV,{"在编","调岗","优化","新增"}))} -> 48 | P4: {=SUM(COUNTIFS(人员调整计划!$E:$E,$A4,人员调整计划!BW:BW,{"在编","调岗","优化","新增"}))} -> 48
C5: 优化 | D5: 11 | E5: {=SUM(COUNTIFS(人员调整计划!$E:$E,$A4,人员调整计划!BL:BL,{"优化"}))} -> 0 | F5: {=SUM(COUNTIFS(人员调整计划!$E:$E,$A4,人员调整计划!BM:BM,{"优化"}))} -> 0 | G5: {=SUM(COUNTIFS(人员调整计划!$E:$E,$A4,人员调整计划!BN:BN,{"优化"}))} -> 0 | H5: {=SUM(COUNTIFS(人员调整计划!$E:$E,$A4,人员调整计划!BO:BO,{"优化"}))} -> 2 | I5: {=SUM(COUNTIFS(人员调整计划!$E:$E,$A4,人员调整计划!BP:BP,{"优化"}))} -> 4 | J5: {=SUM(COUNTIFS(人员调整计划!$E:$E,$A4,人员调整计划!BQ:BQ,{"优化"}))} -> 0 | K5: {=SUM(COUNTIFS(人员调整计划!$E:$E,$A4,人员调整计划!BR:BR,{"优化"}))} -> 5 | L5: {=SUM(COUNTIFS(人员调整计划!$E:$E,$A4,人员调整计划!BS:BS,{"优化"}))} -> 0 | M5: {=SUM(COUNTIFS(人员调整计划!$E:$E,$A4,人员调整计划!BT:BT,{"优化"}))} -> 0 | N5: {=SUM(COUNTIFS(人员调整计划!$E:$E,$A4,人员调整计划!BU:BU,{"优化"}))} -> 0 | O5: {=SUM(COUNTIFS(人员调整计划!$E:$E,$A4,人员调整计划!BV:BV,{"优化"}))} -> 0 | P5: {=SUM(COUNTIFS(人员调整计划!$E:$E,$A4,人员调整计划!BW:BW,{"优化"}))} -> 0
C6: 调岗 | D6: 7 | E6: {=SUM(COUNTIFS(人员调整计划!$E:$E,$A4,人员调整计划!BL:BL,{"调岗"}))} -> 0 | F6: {=SUM(COUNTIFS(人员调整计划!$E:$E,$A4,人员调整计划!BM:BM,{"调岗"}))} -> 0 | G6: {=SUM(COUNTIFS(人员调整计划!$E:$E,$A4,人员调整计划!BN:BN,{"调岗"}))} -> 0 | H6: {=SUM(COUNTIFS(人员调整计划!$E:$E,$A4,人员调整计划!BO:BO,{"调岗"}))} -> 1 | I6: {=SUM(COUNTIFS(人员调整计划!$E:$E,$A4,人员调整计划!BP:BP,{"调岗"}))} -> 0 | J6: {=SUM(COUNTIFS(人员调整计划!$E:$E,$A4,人员调整计划!BQ:BQ,{"调岗"}))} -> 3 | K6: {=SUM(COUNTIFS(人员调整计划!$E:$E,$A4,人员调整计划!BR:BR,{"调岗"}))} -> 3 | L6: {=SUM(COUNTIFS(人员调整计划!$E:$E,$A4,人员调整计划!BS:BS,{"调岗"}))} -> 0 | M6: {=SUM(COUNTIFS(人员调整计划!$E:$E,$A4,人员调整计划!BT:BT,{"调岗"}))} -> 0 | N6: {=SUM(COUNTIFS(人员调整计划!$E:$E,$A4,人员调整计划!BU:BU,{"调岗"}))} -> 0 | O6: {=SUM(COUNTIFS(人员调整计划!$E:$E,$A4,人员调整计划!BV:BV,{"调岗"}))} -> 0 | P6: {=SUM(COUNTIFS(人员调整计划!$E:$E,$A4,人员调整计划!BW:BW,{"调岗"}))} -> 0
C7: 新增 | D7: 14 | E7: {=SUM(COUNTIFS(人员调整计划!$E:$E,$A4,人员调整计划!BL:BL,{"新增"}))} -> 0 | F7: {=SUM(COUNTIFS(人员调整计划!$E:$E,$A4,人员调整计划!BM:BM,{"新增"}))} -> 0 | G7: {=SUM(COUNTIFS(人员调整计划!$E:$E,$A4,人员调整计划!BN:BN,{"新增"}))} -> 0 | H7: {=SUM(COUNTIFS(人员调整计划!$E:$E,$A4,人员调整计划!BO:BO,{"新增"}))} -> 5 | I7: {=SUM(COUNTIFS(人员调整计划!$E:$E,$A4,人员调整计划!BP:BP,{"新增"}))} -> 9 | J7: {=SUM(COUNTIFS(人员调整计划!$E:$E,$A4,人员调整计划!BQ:BQ,{"新增"}))} -> 0 | K7: {=SUM(COUNTIFS(人员调整计划!$E:$E,$A4,人员调整计划!BR:BR,{"新增"}))} -> 0 | L7: {=SUM(COUNTIFS(人员调整计划!$E:$E,$A4,人员调整计划!BS:BS,{"新增"}))} -> 0 | M7: {=SUM(COUNTIFS(人员调整计划!$E:$E,$A4,人员调整计划!BT:BT,{"新增"}))} -> 0 | N7: {=SUM(COUNTIFS(人员调整计划!$E:$E,$A4,人员调整计划!BU:BU,{"新增"}))} -> 0 | O7: {=SUM(COUNTIFS(人员调整计划!$E:$E,$A4,人员调整计划!BV:BV,{"新增"}))} -> 0 | P7: {=SUM(COUNTIFS(人员调整计划!$E:$E,$A4,人员调整计划!BW:BW,{"新增"}))} -> 0
B8: 知识化 | C8: 本科以上占比（不含安保、保洁、司机、电工） | D8: =P8 -> 0.375 | E8: {=SUMPRODUCT((人员调整计划!$E:$E=$A4)*ISNUMBER(MATCH(TRIM(人员调整计划!$AB:$AB),{"二本","一本","双一流","211","985"},0))*ISNUMBER(MATCH(TRIM(人员调整计划!BL:BL),{"在编","新增","优化","调岗"},0))*ISNUMBER(MATCH(TRIM(人员调整计划!$C:$C),{"部长","文控","安保处代主管","专项事务监察处","综合物料库","接待处","行政事务处","特种设备管理处","工程项目管理处"},0)))/IFERROR(SUMPRODUCT((人员调整计划!$G:$G=$A4)*ISNUMBER(MATCH(TRIM(人员调整计划!BL:BL),{"在编","新增","优化","调岗"},0))*ISNUMBER(MATCH(TRIM(人员调整计划!$C:$C),{"部长","文控","安保处代主管","专项事务监察处","综合物料库","接待处","行政事务处","特种设备管理处","工程项目管理处"},0))),1)} -> 0.25 | F8: {=SUMPRODUCT((人员调整计划!$E:$E=$A4)*ISNUMBER(MATCH(TRIM(人员调整计划!$AB:$AB),{"二本","一本","双一流","211","985"},0))*ISNUMBER(MATCH(TRIM(人员调整计划!BM:BM),{"在编","新增","优化","调岗"},0))*ISNUMBER(MATCH(TRIM(人员调整计划!$C:$C),{"部长","文控","安保处代主管","专项事务监察处","综合物料库","接待处","行政事务处","特种设备管理处","工程项目管理处"},0)))/IFERROR(SUMPRODUCT((人员调整计划!$G:$G=$A4)*ISNUMBER(MATCH(TRIM(人员调整计划!BM:BM),{"在编","新增","优化","调岗"},0))*ISNUMBER(MATCH(TRIM(人员调整计划!$C:$C),{"部长","文控","安保处代主管","专项事务监察处","综合物料库","接待处","行政事务处","特种设备管理处","工程项目管理处"},0))),1)} -> 0.25 | G8: {=SUMPRODUCT((人员调整计划!$E:$E=$A4)*ISNUMBER(MATCH(TRIM(人员调整计划!$AB:$AB),{"二本","一本","双一流","211","985"},0))*ISNUMBER(MATCH(TRIM(人员调整计划!BN:BN),{"在编","新增","优化","调岗"},0))*ISNUMBER(MATCH(TRIM(人员调整计划!$C:$C),{"部长","文控","安保处代主管","专项事务监察处","综合物料库","接待处","行政事务处","特种设备管理处","工程项目管理处"},0)))/IFERROR(SUMPRODUCT((人员调整计划!$G:$G=$A4)*ISNUMBER(MATCH(TRIM(人员调整计划!BN:BN),{"在编","新增","优化","调岗"},0))*ISNUMBER(MATCH(TRIM(人员调整计划!$C:$C),{"部长","文控","安保处代主管","专项事务监察处","综合物料库","接待处","行政事务处","特种设备管理处","工程项目管理处"},0))),1)} -> 0.25 | H8: {=SUMPRODUCT((人员调整计划!$E:$E=$A4)*ISNUMBER(MATCH(TRIM(人员调整计划!$AB:$AB),{"二本","一本","双一流","211","985"},0))*ISNUMBER(MATCH(TRIM(人员调整计划!BO:BO),{"在编","新增","优化","调岗"},0))*ISNUMBER(MATCH(TRIM(人员调整计划!$C:$C),{"部长","文控","安保处代主管","专项事务监察处","综合物料库","接待处","行政事务处","特种设备管理处","工程项目管理处"},0)))/IFERROR(SUMPRODUCT((人员调整计划!$G:$G=$A4)*ISNUMBER(MATCH(TRIM(人员调整计划!BO:BO),{"在编","新增","优化","调岗"},0))*ISNUMBER(MATCH(TRIM(人员调整计划!$C:$C),{"部长","文控","安保处代主管","专项事务监察处","综合物料库","接待处","行政事务处","特种设备管理处","工程项目管理处"},0))),1)} -> 0.28 | I8: {=SUMPRODUCT((人员调整计划!$E:$E=$A4)*ISNUMBER(MATCH(TRIM(人员调整计划!$AB:$AB),{"二本","一本","双一流","211","985"},0))*ISNUMBER(MATCH(TRIM(人员调整计划!BP:BP),{"在编","新增","优化","调岗"},0))*ISNUMBER(MATCH(TRIM(人员调整计划!$C:$C),{"部长","文控","安保处代主管","专项事务监察处","综合物料库","接待处","行政事务处","特种设备管理处","工程项目管理处"},0)))/IFERROR(SUMPRODUCT((人员调整计划!$G:$G=$A4)*ISNUMBER(MATCH(TRIM(人员调整计划!BP:BP),{"在编","新增","优化","调岗"},0))*ISNUMBER(MATCH(TRIM(人员调整计划!$C:$C),{"部长","文控","安保处代主管","专项事务监察处","综合物料库","接待处","行政事务处","特种设备管理处","工程项目管理处"},0))),1)} -> 0.37931034 | J8: {=SUMPRODUCT((人员调整计划!$E:$E=$A4)*ISNUMBER(MATCH(TRIM(人员调整计划!$AB:$AB),{"二本","一本","双一流","211","985"},0))*ISNUMBER(MATCH(TRIM(人员调整计划!BQ:BQ),{"在编","新增","优化","调岗"},0))*ISNUMBER(MATCH(TRIM(人员调整计划!$C:$C),{"部长","文控","安保处代主管","专项事务监察处","综合物料库","接待处","行政事务处","特种设备管理处","工程项目管理处"},0)))/IFERROR(SUMPRODUCT((人员调整计划!$G:$G=$A4)*ISNUMBER(MATCH(TRIM(人员调整计划!BQ:BQ),{"在编","新增","优化","调岗"},0))*ISNUMBER(MATCH(TRIM(人员调整计划!$C:$C),{"部长","文控","安保处代主管","专项事务监察处","综合物料库","接待处","行政事务处","特种设备管理处","工程项目管理处"},0))),1)} -> 0.37037037 | K8: {=SUMPRODUCT((人员调整计划!$E:$E=$A4)*ISNUMBER(MATCH(TRIM(人员调整计划!$AB:$AB),{"二本","一本","双一流","211","985"},0))*ISNUMBER(MATCH(TRIM(人员调整计划!BR:BR),{"在编","新增","优化","调岗"},0))*ISNUMBER(MATCH(TRIM(人员调整计划!$C:$C),{"部长","文控","安保处代主管","专项事务监察处","综合物料库","接待处","行政事务处","特种设备管理处","工程项目管理处"},0)))/IFERROR(SUMPRODUCT((人员调整计划!$G:$G=$A4)*ISNUMBER(MATCH(TRIM(人员调整计划!BR:BR),{"在编","新增","优化","调岗"},0))*ISNUMBER(MATCH(TRIM(人员调整计划!$C:$C),{"部长","文控","安保处代主管","专项事务监察处","综合物料库","接待处","行政事务处","特种设备管理处","工程项目管理处"},0))),1)} -> 0.36 | L8: {=SUMPRODUCT((人员调整计划!$E:$E=$A4)*ISNUMBER(MATCH(TRIM(人员调整计划!$AB:$AB),{"二本","一本","双一流","211","985"},0))*ISNUMBER(MATCH(TRIM(人员调整计划!BS:BS),{"在编","新增","优化","调岗"},0))*ISNUMBER(MATCH(TRIM(人员调整计划!$C:$C),{"部长","文控","安保处代主管","专项事务监察处","综合物料库","接待处","行政事务处","特种设备管理处","工程项目管理处"},0)))/IFERROR(SUMPRODUCT((人员调整计划!$G:$G=$A4)*ISNUMBER(MATCH(TRIM(人员调整计划!BS:BS),{"在编","新增","优化","调岗"},0))*ISNUMBER(MATCH(TRIM(人员调整计划!$C:$C),{"部长","文控","安保处代主管","专项事务监察处","综合物料库","接待处","行政事务处","特种设备管理处","工程项目管理处"},0))),1)} -> 0.375 | M8: {=SUMPRODUCT((人员调整计划!$E:$E=$A4)*ISNUMBER(MATCH(TRIM(人员调整计划!$AB:$AB),{"二本","一本","双一流","211","985"},0))*ISNUMBER(MATCH(TRIM(人员调整计划!BT:BT),{"在编","新增","优化","调岗"},0))*ISNUMBER(MATCH(TRIM(人员调整计划!$C:$C),{"部长","文控","安保处代主管","专项事务监察处","综合物料库","接待处","行政事务处","特种设备管理处","工程项目管理处"},0)))/IFERROR(SUMPRODUCT((人员调整计划!$G:$G=$A4)*ISNUMBER(MATCH(TRIM(人员调整计划!BT:BT),{"在编","新增","优化","调岗"},0))*ISNUMBER(MATCH(TRIM(人员调整计划!$C:$C),{"部长","文控","安保处代主管","专项事务监察处","综合物料库","接待处","行政事务处","特种设备管理处","工程项目管理处"},0))),1)} -> 0.375 | N8: {=SUMPRODUCT((人员调整计划!$E:$E=$A4)*ISNUMBER(MATCH(TRIM(人员调整计划!$AB:$AB),{"二本","一本","双一流","211","985"},0))*ISNUMBER(MATCH(TRIM(人员调整计划!BU:BU),{"在编","新增","优化","调岗"},0))*ISNUMBER(MATCH(TRIM(人员调整计划!$C:$C),{"部长","文控","安保处代主管","专项事务监察处","综合物料库","接待处","行政事务处","特种设备管理处","工程项目管理处"},0)))/IFERROR(SUMPRODUCT((人员调整计划!$G:$G=$A4)*ISNUMBER(MATCH(TRIM(人员调整计划!BU:BU),{"在编","新增","优化","调岗"},0))*ISNUMBER(MATCH(TRIM(人员调整计划!$C:$C),{"部长","文控","安保处代主管","专项事务监察处","综合物料库","接待处","行政事务处","特种设备管理处","工程项目管理处"},0))),1)} -> 0.375 | O8: {=SUMPRODUCT((人员调整计划!$E:$E=$A4)*ISNUMBER(MATCH(TRIM(人员调整计划!$AB:$AB),{"二本","一本","双一流","211","985"},0))*ISNUMBER(MATCH(TRIM(人员调整计划!BV:BV),{"在编","新增","优化","调岗"},0))*ISNUMBER(MATCH(TRIM(人员调整计划!$C:$C),{"部长","文控","安保处代主管","专项事务监察处","综合物料库","接待处","行政事务处","特种设备管理处","工程项目管理处"},0)))/IFERROR(SUMPRODUCT((人员调整计划!$G:$G=$A4)*ISNUMBER(MATCH(TRIM(人员调整计划!BV:BV),{"在编","新增","优化","调岗"},0))*ISNUMBER(MATCH(TRIM(人员调整计划!$C:$C),{"部长","文控","安保处代主管","专项事务监察处","综合物料库","接待处","行政事务处","特种设备管理处","工程项目管理处"},0))),1)} -> 0.375 | P8: {=SUMPRODUCT((人员调整计划!$E:$E=$A4)*ISNUMBER(MATCH(TRIM(人员调整计划!$AB:$AB),{"二本","一本","双一流","211","985"},0))*ISNUMBER(MATCH(TRIM(人员调整计划!BW:BW),{"在编","新增","优化","调岗"},0))*ISNUMBER(MATCH(TRIM(人员调整计划!$C:$C),{"部长","文控","安保处代主管","专项事务监察处","综合物料库","接待处","行政事务处","特种设备管理处","工程项目管理处"},0)))/IFERROR(SUMPRODUCT((人员调整计划!$G:$G=$A4)*ISNUMBER(MATCH(TRIM(人员调整计划!BW:BW),{"在编","新增","优化","调岗"},0))*ISNUMBER(MATCH(TRIM(人员调整计划!$C:$C),{"部长","文控","安保处代主管","专项事务监察处","综合物料库","接待处","行政事务处","特种设备管理处","工程项目管理处"},0))),1)} -> 0.375
C9: 大专及以上占比（安保、保洁、司机、电工） | D9: =P9 -> 0.18181818 | E9: {=SUMPRODUCT((人员调整计划!$E:$E=$A4)*ISNUMBER(MATCH(TRIM(人员调整计划!$AB:$AB),{"大专","二本","一本","双一流","211","985"},0))*ISNUMBER(MATCH(TRIM(人员调整计划!BL:BL),{"在编","新增","优化","调岗"},0))*ISNUMBER(MATCH(TRIM(人员调整计划!$C:$C),{"安保处","保洁","电工","司机"},0)))/IFERROR(SUMPRODUCT((人员调整计划!$G:$G=$A4)*ISNUMBER(MATCH(TRIM(人员调整计划!BL:BL),{"在编","新增","优化","调岗"},0))*ISNUMBER(MATCH(TRIM(人员调整计划!$C:$C),{"安保处","保洁","电工","司机"},0))),1)} -> 0.095238095 | F9: {=SUMPRODUCT((人员调整计划!$E:$E=$A4)*ISNUMBER(MATCH(TRIM(人员调整计划!$AB:$AB),{"大专","二本","一本","双一流","211","985"},0))*ISNUMBER(MATCH(TRIM(人员调整计划!BM:BM),{"在编","新增","优化","调岗"},0))*ISNUMBER(MATCH(TRIM(人员调整计划!$C:$C),{"安保处","保洁","电工","司机"},0)))/IFERROR(SUMPRODUCT((人员调整计划!$G:$G=$A4)*ISNUMBER(MATCH(TRIM(人员调整计划!BM:BM),{"在编","新增","优化","调岗"},0))*ISNUMBER(MATCH(TRIM(人员调整计划!$C:$C),{"安保处","保洁","电工","司机"},0))),1)} -> 0.095238095 | G9: {=SUMPRODUCT((人员调整计划!$E:$E=$A4)*ISNUMBER(MATCH(TRIM(人员调整计划!$AB:$AB),{"大专","二本","一本","双一流","211","985"},0))*ISNUMBER(MATCH(TRIM(人员调整计划!BN:BN),{"在编","新增","优化","调岗"},0))*ISNUMBER(MATCH(TRIM(人员调整计划!$C:$C),{"安保处","保洁","电工","司机"},0)))/IFERROR(SUMPRODUCT((人员调整计划!$G:$G=$A4)*ISNUMBER(MATCH(TRIM(人员调整计划!BN:BN),{"在编","新增","优化","调岗"},0))*ISNUMBER(MATCH(TRIM(人员调整计划!$C:$C),{"安保处","保洁","电工","司机"},0))),1)} -> 0.095238095 | H9: {=SUMPRODUCT((人员调整计划!$E:$E=$A4)*ISNUMBER(MATCH(TRIM(人员调整计划!$AB:$AB),{"大专","二本","一本","双一流","211","985"},0))*ISNUMBER(MATCH(TRIM(人员调整计划!BO:BO),{"在编","新增","优化","调岗"},0))*ISNUMBER(MATCH(TRIM(人员调整计划!$C:$C),{"安保处","保洁","电工","司机"},0)))/IFERROR(SUMPRODUCT((人员调整计划!$G:$G=$A4)*ISNUMBER(MATCH(TRIM(人员调整计划!BO:BO),{"在编","新增","优化","调岗"},0))*ISNUMBER(MATCH(TRIM(人员调整计划!$C:$C),{"安保处","保洁","电工","司机"},0))),1)} -> 0.095238095 | I9: {=SUMPRODUCT((人员调整计划!$E:$E=$A4)*ISNUMBER(MATCH(TRIM(人员调整计划!$AB:$AB),{"大专","二本","一本","双一流","211","985"},0))*ISNUMBER(MATCH(TRIM(人员调整计划!BP:BP),{"在编","新增","优化","调岗"},0))*ISNUMBER(MATCH(TRIM(人员调整计划!$C:$C),{"安保处","保洁","电工","司机"},0)))/IFERROR(SUMPRODUCT((人员调整计划!$G:$G=$A4)*ISNUMBER(MATCH(TRIM(人员调整计划!BP:BP),{"在编","新增","优化","调岗"},0))*ISNUMBER(MATCH(TRIM(人员调整计划!$C:$C),{"安保处","保洁","电工","司机"},0))),1)} -> 0.10526316 | J9: {=SUMPRODUCT((人员调整计划!$E:$E=$A4)*ISNUMBER(MATCH(TRIM(人员调整计划!$AB:$AB),{"大专","二本","一本","双一流","211","985"},0))*ISNUMBER(MATCH(TRIM(人员调整计划!BQ:BQ),{"在编","新增","优化","调岗"},0))*ISNUMBER(MATCH(TRIM(人员调整计划!$C:$C),{"安保处","保洁","电工","司机"},0)))/IFERROR(SUMPRODUCT((人员调整计划!$G:$G=$A4)*ISNUMBER(MATCH(TRIM(人员调整计划!BQ:BQ),{"在编","新增","优化","调岗"},0))*ISNUMBER(MATCH(TRIM(人员调整计划!$C:$C),{"安保处","保洁","电工","司机"},0))),1)} -> 0.11764706 | K9: {=SUMPRODUCT((人员调整计划!$E:$E=$A4)*ISNUMBER(MATCH(TRIM(人员调整计划!$AB:$AB),{"大专","二本","一本","双一流","211","985"},0))*ISNUMBER(MATCH(TRIM(人员调整计划!BR:BR),{"在编","新增","优化","调岗"},0))*ISNUMBER(MATCH(TRIM(人员调整计划!$C:$C),{"安保处","保洁","电工","司机"},0)))/IFERROR(SUMPRODUCT((人员调整计划!$G:$G=$A4)*ISNUMBER(MATCH(TRIM(人员调整计划!BR:BR),{"在编","新增","优化","调岗"},0))*ISNUMBER(MATCH(TRIM(人员调整计划!$C:$C),{"安保处","保洁","电工","司机"},0))),1)} -> 0.11764706 | L9: {=SUMPRODUCT((人员调整计划!$E:$E=$A4)*ISNUMBER(MATCH(TRIM(人员调整计划!$AB:$AB),{"大专","二本","一本","双一流","211","985"},0))*ISNUMBER(MATCH(TRIM(人员调整计划!BS:BS),{"在编","新增","优化","调岗"},0))*ISNUMBER(MATCH(TRIM(人员调整计划!$C:$C),{"安保处","保洁","电工","司机"},0)))/IFERROR(SUMPRODUCT((人员调整计划!$G:$G=$A4)*ISNUMBER(MATCH(TRIM(人员调整计划!BS:BS),{"在编","新增","优化","调岗"},0))*ISNUMBER(MATCH(TRIM(人员调整计划!$C:$C),{"安保处","保洁","电工","司机"},0))),1)} -> 0.18181818 | M9: {=SUMPRODUCT((人员调整计划!$E:$E=$A4)*ISNUMBER(MATCH(TRIM(人员调整计划!$AB:$AB),{"大专","二本","一本","双一流","211","985"},0))*ISNUMBER(MATCH(TRIM(人员调整计划!BT:BT),{"在编","新增","优化","调岗"},0))*ISNUMBER(MATCH(TRIM(人员调整计划!$C:$C),{"安保处","保洁","电工","司机"},0)))/IFERROR(SUMPRODUCT((人员调整计划!$G:$G=$A4)*ISNUMBER(MATCH(TRIM(人员调整计划!BT:BT),{"在编","新增","优化","调岗"},0))*ISNUMBER(MATCH(TRIM(人员调整计划!$C:$C),{"安保处","保洁","电工","司机"},0))),1)} -> 0.18181818 | N9: {=SUMPRODUCT((人员调整计划!$E:$E=$A4)*ISNUMBER(MATCH(TRIM(人员调整计划!$AB:$AB),{"大专","二本","一本","双一流","211","985"},0))*ISNUMBER(MATCH(TRIM(人员调整计划!BU:BU),{"在编","新增","优化","调岗"},0))*ISNUMBER(MATCH(TRIM(人员调整计划!$C:$C),{"安保处","保洁","电工","司机"},0)))/IFERROR(SUMPRODUCT((人员调整计划!$G:$G=$A4)*ISNUMBER(MATCH(TRIM(人员调整计划!BU:BU),{"在编","新增","优化","调岗"},0))*ISNUMBER(MATCH(TRIM(人员调整计划!$C:$C),{"安保处","保洁","电工","司机"},0))),1)} -> 0.18181818 | O9: {=SUMPRODUCT((人员调整计划!$E:$E=$A4)*ISNUMBER(MATCH(TRIM(人员调整计划!$AB:$AB),{"大专","二本","一本","双一流","211","985"},0))*ISNUMBER(MATCH(TRIM(人员调整计划!BV:BV),{"在编","新增","优化","调岗"},0))*ISNUMBER(MATCH(TRIM(人员调整计划!$C:$C),{"安保处","保洁","电工","司机"},0)))/IFERROR(SUMPRODUCT((人员调整计划!$G:$G=$A4)*ISNUMBER(MATCH(TRIM(人员调整计划!BV:BV),{"在编","新增","优化","调岗"},0))*ISNUMBER(MATCH(TRIM(人员调整计划!$C:$C),{"安保处","保洁","电工","司机"},0))),1)} -> 0.18181818 | P9: {=SUMPRODUCT((人员调整计划!$E:$E=$A4)*ISNUMBER(MATCH(TRIM(人员调整计划!$AB:$AB),{"大专","二本","一本","双一流","211","985"},0))*ISNUMBER(MATCH(TRIM(人员调整计划!BW:BW),{"在编","新增","优化","调岗"},0))*ISNUMBER(MATCH(TRIM(人员调整计划!$C:$C),{"安保处","保洁","电工","司机"},0)))/IFERROR(SUMPRODUCT((人员调整计划!$G:$G=$A4)*ISNUMBER(MATCH(TRIM(人员调整计划!BW:BW),{"在编","新增","优化","调岗"},0))*ISNUMBER(MATCH(TRIM(人员调整计划!$C:$C),{"安保处","保洁","电工","司机"},0))),1)} -> 0.18181818
B10: 年轻化 | C10: 30岁以下占比 | D10: =P10 -> 0.625 | E10: {=SUM(COUNTIFS(人员调整计划!$G:$G,$A4,人员调整计划!$AH:$AH,"<30",人员调整计划!BL:BL,{"在编","调岗","新增","优化"}))/E4} -> 0.44230769 | F10: {=SUM(COUNTIFS(人员调整计划!$G:$G,$A4,人员调整计划!$AH:$AH,"<30",人员调整计划!BM:BM,{"在编","调岗","新增","优化"}))/F4} -> 0.44230769 | G10: {=SUM(COUNTIFS(人员调整计划!$G:$G,$A4,人员调整计划!$AH:$AH,"<30",人员调整计划!BN:BN,{"在编","调岗","新增","优化"}))/G4} -> 0.44230769 | H10: {=SUM(COUNTIFS(人员调整计划!$G:$G,$A4,人员调整计划!$AH:$AH,"<30",人员调整计划!BO:BO,{"在编","调岗","新增","优化"}))/H4} -> 0.47368421 | I10: {=SUM(COUNTIFS(人员调整计划!$G:$G,$A4,人员调整计划!$AH:$AH,"<30",人员调整计划!BP:BP,{"在编","调岗","新增","优化"}))/I4} -> 0.53968254 | J10: {=SUM(COUNTIFS(人员调整计划!$G:$G,$A4,人员调整计划!$AH:$AH,"<30",人员调整计划!BQ:BQ,{"在编","调岗","新增","优化"}))/J4} -> 0.55932203 | K10: {=SUM(COUNTIFS(人员调整计划!$G:$G,$A4,人员调整计划!$AH:$AH,"<30",人员调整计划!BR:BR,{"在编","调岗","新增","优化"}))/K4} -> 0.55357143 | L10: {=SUM(COUNTIFS(人员调整计划!$G:$G,$A4,人员调整计划!$AH:$AH,"<30",人员调整计划!BS:BS,{"在编","调岗","新增","优化"}))/L4} -> 0.625 | M10: {=SUM(COUNTIFS(人员调整计划!$G:$G,$A4,人员调整计划!$AH:$AH,"<30",人员调整计划!BT:BT,{"在编","调岗","新增","优化"}))/M4} -> 0.625 | N10: {=SUM(COUNTIFS(人员调整计划!$G:$G,$A4,人员调整计划!$AH:$AH,"<30",人员调整计划!BU:BU,{"在编","调岗","新增","优化"}))/N4} -> 0.625 | O10: {=SUM(COUNTIFS(人员调整计划!$G:$G,$A4,人员调整计划!$AH:$AH,"<30",人员调整计划!BV:BV,{"在编","调岗","新增","优化"}))/O4} -> 0.625 | P10: {=SUM(COUNTIFS(人员调整计划!$G:$G,$A4,人员调整计划!$AH:$AH,"<30",人员调整计划!BW:BW,{"在编","调岗","新增","优化"}))/P4} -> 0.625
B11: 男女比例 | C11: 男性占比 | D11: =P11 -> 0.70833333 | E11: {=SUM(COUNTIFS(人员调整计划!$G:$G,$A4,人员调整计划!$S:$S,"男",人员调整计划!BL:BL,{"在编","调岗","新增","优化"}))/E4} -> 0.63461538 | F11: {=SUM(COUNTIFS(人员调整计划!$G:$G,$A4,人员调整计划!$S:$S,"男",人员调整计划!BM:BM,{"在编","调岗","新增","优化"}))/F4} -> 0.63461538 | G11: {=SUM(COUNTIFS(人员调整计划!$G:$G,$A4,人员调整计划!$S:$S,"男",人员调整计划!BN:BN,{"在编","调岗","新增","优化"}))/G4} -> 0.63461538 | H11: {=SUM(COUNTIFS(人员调整计划!$G:$G,$A4,人员调整计划!$S:$S,"男",人员调整计划!BO:BO,{"在编","调岗","新增","优化"}))/H4} -> 0.66666667 | I11: {=SUM(COUNTIFS(人员调整计划!$G:$G,$A4,人员调整计划!$S:$S,"男",人员调整计划!BP:BP,{"在编","调岗","新增","优化"}))/I4} -> 0.63492063 | J11: {=SUM(COUNTIFS(人员调整计划!$G:$G,$A4,人员调整计划!$S:$S,"男",人员调整计划!BQ:BQ,{"在编","调岗","新增","优化"}))/J4} -> 0.6440678 | K11: {=SUM(COUNTIFS(人员调整计划!$G:$G,$A4,人员调整计划!$S:$S,"男",人员调整计划!BR:BR,{"在编","调岗","新增","优化"}))/K4} -> 0.64285714 | L11: {=SUM(COUNTIFS(人员调整计划!$G:$G,$A4,人员调整计划!$S:$S,"男",人员调整计划!BS:BS,{"在编","调岗","新增","优化"}))/L4} -> 0.70833333 | M11: {=SUM(COUNTIFS(人员调整计划!$G:$G,$A4,人员调整计划!$S:$S,"男",人员调整计划!BT:BT,{"在编","调岗","新增","优化"}))/M4} -> 0.70833333 | N11: {=SUM(COUNTIFS(人员调整计划!$G:$G,$A4,人员调整计划!$S:$S,"男",人员调整计划!BU:BU,{"在编","调岗","新增","优化"}))/N4} -> 0.70833333 | O11: {=SUM(COUNTIFS(人员调整计划!$G:$G,$A4,人员调整计划!$S:$S,"男",人员调整计划!BV:BV,{"在编","调岗","新增","优化"}))/O4} -> 0.70833333 | P11: {=SUM(COUNTIFS(人员调整计划!$G:$G,$A4,人员调整计划!$S:$S,"男",人员调整计划!BW:BW,{"在编","调岗","新增","优化"}))/P4} -> 0.70833333
B12: 岗位匹配 | C12: 本专业占比 | D12: =P12 -> 0.6875 | E12: {=SUM(COUNTIFS(人员调整计划!$G:$G,$A4,人员调整计划!$AC:$AC,"直接",人员调整计划!BL:BL,{"在编","调岗","新增","优化"}))/E4} -> 0.71153846 | F12: {=SUM(COUNTIFS(人员调整计划!$G:$G,$A4,人员调整计划!$AC:$AC,"直接",人员调整计划!BM:BM,{"在编","调岗","新增","优化"}))/F4} -> 0.71153846 | G12: {=SUM(COUNTIFS(人员调整计划!$G:$G,$A4,人员调整计划!$AC:$AC,"直接",人员调整计划!BN:BN,{"在编","调岗","新增","优化"}))/G4} -> 0.71153846 | H12: {=SUM(COUNTIFS(人员调整计划!$G:$G,$A4,人员调整计划!$AC:$AC,"直接",人员调整计划!BO:BO,{"在编","调岗","新增","优化"}))/H4} -> 0.70175439 | I12: {=SUM(COUNTIFS(人员调整计划!$G:$G,$A4,人员调整计划!$AC:$AC,"直接",人员调整计划!BP:BP,{"在编","调岗","新增","优化"}))/I4} -> 0.6984127 | J12: {=SUM(COUNTIFS(人员调整计划!$G:$G,$A4,人员调整计划!$AC:$AC,"直接",人员调整计划!BQ:BQ,{"在编","调岗","新增","优化"}))/J4} -> 0.6779661 | K12: {=SUM(COUNTIFS(人员调整计划!$G:$G,$A4,人员调整计划!$AC:$AC,"直接",人员调整计划!BR:BR,{"在编","调岗","新增","优化"}))/K4} -> 0.67857143 | L12: {=SUM(COUNTIFS(人员调整计划!$G:$G,$A4,人员调整计划!$AC:$AC,"直接",人员调整计划!BS:BS,{"在编","调岗","新增","优化"}))/L4} -> 0.6875 | M12: {=SUM(COUNTIFS(人员调整计划!$G:$G,$A4,人员调整计划!$AC:$AC,"直接",人员调整计划!BT:BT,{"在编","调岗","新增","优化"}))/M4} -> 0.6875 | N12: {=SUM(COUNTIFS(人员调整计划!$G:$G,$A4,人员调整计划!$AC:$AC,"直接",人员调整计划!BU:BU,{"在编","调岗","新增","优化"}))/N4} -> 0.6875 | O12: {=SUM(COUNTIFS(人员调整计划!$G:$G,$A4,人员调整计划!$AC:$AC,"直接",人员调整计划!BV:BV,{"在编","调岗","新增","优化"}))/O4} -> 0.6875 | P12: {=SUM(COUNTIFS(人员调整计划!$G:$G,$A4,人员调整计划!$AC:$AC,"直接",人员调整计划!BW:BW,{"在编","调岗","新增","优化"}))/P4} -> 0.6875
B13: 六边形 | C13: 财务BP-人数 | D13: =P13 -> 0.041666667 | E13: {=SUM(COUNTIFS(人员调整计划!$G:$G,$A4,人员调整计划!$AD:$AD,"财务",人员调整计划!BL:BL,{"在编","调岗","新增","优化"}))/E4} -> 0.019230769 | F13: {=SUM(COUNTIFS(人员调整计划!$G:$G,$A4,人员调整计划!$AD:$AD,"财务",人员调整计划!BM:BM,{"在编","调岗","新增","优化"}))/F4} -> 0.019230769 | G13: {=SUM(COUNTIFS(人员调整计划!$G:$G,$A4,人员调整计划!$AD:$AD,"财务",人员调整计划!BN:BN,{"在编","调岗","新增","优化"}))/G4} -> 0.019230769 | H13: {=SUM(COUNTIFS(人员调整计划!$G:$G,$A4,人员调整计划!$AD:$AD,"财务",人员调整计划!BO:BO,{"在编","调岗","新增","优化"}))/H4} -> 0.01754386 | I13: {=SUM(COUNTIFS(人员调整计划!$G:$G,$A4,人员调整计划!$AD:$AD,"财务",人员调整计划!BP:BP,{"在编","调岗","新增","优化"}))/I4} -> 0.031746032 | J13: {=SUM(COUNTIFS(人员调整计划!$G:$G,$A4,人员调整计划!$AD:$AD,"财务",人员调整计划!BQ:BQ,{"在编","调岗","新增","优化"}))/J4} -> 0.033898305 | K13: {=SUM(COUNTIFS(人员调整计划!$G:$G,$A4,人员调整计划!$AD:$AD,"财务",人员调整计划!BR:BR,{"在编","调岗","新增","优化"}))/K4} -> 0.035714286 | L13: {=SUM(COUNTIFS(人员调整计划!$G:$G,$A4,人员调整计划!$AD:$AD,"财务",人员调整计划!BS:BS,{"在编","调岗","新增","优化"}))/L4} -> 0.041666667 | M13: {=SUM(COUNTIFS(人员调整计划!$G:$G,$A4,人员调整计划!$AD:$AD,"财务",人员调整计划!BT:BT,{"在编","调岗","新增","优化"}))/M4} -> 0.041666667 | N13: {=SUM(COUNTIFS(人员调整计划!$G:$G,$A4,人员调整计划!$AD:$AD,"财务",人员调整计划!BU:BU,{"在编","调岗","新增","优化"}))/N4} -> 0.041666667 | O13: {=SUM(COUNTIFS(人员调整计划!$G:$G,$A4,人员调整计划!$AD:$AD,"财务",人员调整计划!BV:BV,{"在编","调岗","新增","优化"}))/O4} -> 0.041666667 | P13: {=SUM(COUNTIFS(人员调整计划!$G:$G,$A4,人员调整计划!$AD:$AD,"财务",人员调整计划!BW:BW,{"在编","调岗","新增","优化"}))/P4} -> 0.041666667
C14: 法务BP-人数 | D14: =P14 -> 0.020833333 | E14: {=SUM(COUNTIFS(人员调整计划!$G:$G,$A4,人员调整计划!$AD:$AD,"法务",人员调整计划!BL:BL,{"在编","调岗","新增","优化"}))/E4} -> 0 | F14: {=SUM(COUNTIFS(人员调整计划!$G:$G,$A4,人员调整计划!$AD:$AD,"法务",人员调整计划!BM:BM,{"在编","调岗","新增","优化"}))/F4} -> 0 | G14: {=SUM(COUNTIFS(人员调整计划!$G:$G,$A4,人员调整计划!$AD:$AD,"法务",人员调整计划!BN:BN,{"在编","调岗","新增","优化"}))/G4} -> 0 | H14: {=SUM(COUNTIFS(人员调整计划!$G:$G,$A4,人员调整计划!$AD:$AD,"法务",人员调整计划!BO:BO,{"在编","调岗","新增","优化"}))/H4} -> 0 | I14: {=SUM(COUNTIFS(人员调整计划!$G:$G,$A4,人员调整计划!$AD:$AD,"法务",人员调整计划!BP:BP,{"在编","调岗","新增","优化"}))/I4} -> 0.015873016 | J14: {=SUM(COUNTIFS(人员调整计划!$G:$G,$A4,人员调整计划!$AD:$AD,"法务",人员调整计划!BQ:BQ,{"在编","调岗","新增","优化"}))/J4} -> 0.016949153 | K14: {=SUM(COUNTIFS(人员调整计划!$G:$G,$A4,人员调整计划!$AD:$AD,"法务",人员调整计划!BR:BR,{"在编","调岗","新增","优化"}))/K4} -> 0.017857143 | L14: {=SUM(COUNTIFS(人员调整计划!$G:$G,$A4,人员调整计划!$AD:$AD,"法务",人员调整计划!BS:BS,{"在编","调岗","新增","优化"}))/L4} -> 0.020833333 | M14: {=SUM(COUNTIFS(人员调整计划!$G:$G,$A4,人员调整计划!$AD:$AD,"法务",人员调整计划!BT:BT,{"在编","调岗","新增","优化"}))/M4} -> 0.020833333 | N14: {=SUM(COUNTIFS(人员调整计划!$G:$G,$A4,人员调整计划!$AD:$AD,"法务",人员调整计划!BU:BU,{"在编","调岗","新增","优化"}))/N4} -> 0.020833333 | O14: {=SUM(COUNTIFS(人员调整计划!$G:$G,$A4,人员调整计划!$AD:$AD,"法务",人员调整计划!BV:BV,{"在编","调岗","新增","优化"}))/O4} -> 0.020833333 | P14: {=SUM(COUNTIFS(人员调整计划!$G:$G,$A4,人员调整计划!$AD:$AD,"法务",人员调整计划!BW:BW,{"在编","调岗","新增","优化"}))/P4} -> 0.020833333
C15: HR BP-人数 | D15: =P15 -> 0.020833333 | E15: {=SUM(COUNTIFS(人员调整计划!$G:$G,$A4,人员调整计划!$AD:$AD,"HR",人员调整计划!BL:BL,{"在编","调岗","新增","优化"}))/E4} -> 0.019230769 | F15: {=SUM(COUNTIFS(人员调整计划!$G:$G,$A4,人员调整计划!$AD:$AD,"HR",人员调整计划!BM:BM,{"在编","调岗","新增","优化"}))/F4} -> 0.019230769 | G15: {=SUM(COUNTIFS(人员调整计划!$G:$G,$A4,人员调整计划!$AD:$AD,"HR",人员调整计划!BN:BN,{"在编","调岗","新增","优化"}))/G4} -> 0.019230769 | H15: {=SUM(COUNTIFS(人员调整计划!$G:$G,$A4,人员调整计划!$AD:$AD,"HR",人员调整计划!BO:BO,{"在编","调岗","新增","优化"}))/H4} -> 0.01754386 | I15: {=SUM(COUNTIFS(人员调整计划!$G:$G,$A4,人员调整计划!$AD:$AD,"HR",人员调整计划!BP:BP,{"在编","调岗","新增","优化"}))/I4} -> 0.015873016 | J15: {=SUM(COUNTIFS(人员调整计划!$G:$G,$A4,人员调整计划!$AD:$AD,"HR",人员调整计划!BQ:BQ,{"在编","调岗","新增","优化"}))/J4} -> 0.016949153 | K15: {=SUM(COUNTIFS(人员调整计划!$G:$G,$A4,人员调整计划!$AD:$AD,"HR",人员调整计划!BR:BR,{"在编","调岗","新增","优化"}))/K4} -> 0.017857143 | L15: {=SUM(COUNTIFS(人员调整计划!$G:$G,$A4,人员调整计划!$AD:$AD,"HR",人员调整计划!BS:BS,{"在编","调岗","新增","优化"}))/L4} -> 0.020833333 | M15: {=SUM(COUNTIFS(人员调整计划!$G:$G,$A4,人员调整计划!$AD:$AD,"HR",人员调整计划!BT:BT,{"在编","调岗","新增","优化"}))/M4} -> 0.020833333 | N15: {=SUM(COUNTIFS(人员调整计划!$G:$G,$A4,人员调整计划!$AD:$AD,"HR",人员调整计划!BU:BU,{"在编","调岗","新增","优化"}))/N4} -> 0.020833333 | O15: {=SUM(COUNTIFS(人员调整计划!$G:$G,$A4,人员调整计划!$AD:$AD,"HR",人员调整计划!BV:BV,{"在编","调岗","新增","优化"}))/O4} -> 0.020833333 | P15: {=SUM(COUNTIFS(人员调整计划!$G:$G,$A4,人员调整计划!$AD:$AD,"HR",人员调整计划!BW:BW,{"在编","调岗","新增","优化"}))/P4} -> 0.020833333
C16: 理工 BP-人数 | D16: =P16 -> 0.020833333 | E16: {=SUM(COUNTIFS(人员调整计划!$G:$G,$A4,人员调整计划!$AD:$AD,"理工",人员调整计划!BL:BL,{"在编","调岗","新增","优化"}))/E4} -> 0.019230769 | F16: {=SUM(COUNTIFS(人员调整计划!$G:$G,$A4,人员调整计划!$AD:$AD,"理工",人员调整计划!BM:BM,{"在编","调岗","新增","优化"}))/F4} -> 0.019230769 | G16: {=SUM(COUNTIFS(人员调整计划!$G:$G,$A4,人员调整计划!$AD:$AD,"理工",人员调整计划!BN:BN,{"在编","调岗","新增","优化"}))/G4} -> 0.019230769 | H16: {=SUM(COUNTIFS(人员调整计划!$G:$G,$A4,人员调整计划!$AD:$AD,"理工",人员调整计划!BO:BO,{"在编","调岗","新增","优化"}))/H4} -> 0.01754386 | I16: {=SUM(COUNTIFS(人员调整计划!$G:$G,$A4,人员调整计划!$AD:$AD,"理工",人员调整计划!BP:BP,{"在编","调岗","新增","优化"}))/I4} -> 0.015873016 | J16: {=SUM(COUNTIFS(人员调整计划!$G:$G,$A4,人员调整计划!$AD:$AD,"理工",人员调整计划!BQ:BQ,{"在编","调岗","新增","优化"}))/J4} -> 0.016949153 | K16: {=SUM(COUNTIFS(人员调整计划!$G:$G,$A4,人员调整计划!$AD:$AD,"理工",人员调整计划!BR:BR,{"在编","调岗","新增","优化"}))/K4} -> 0.017857143 | L16: {=SUM(COUNTIFS(人员调整计划!$G:$G,$A4,人员调整计划!$AD:$AD,"理工",人员调整计划!BS:BS,{"在编","调岗","新增","优化"}))/L4} -> 0.020833333 | M16: {=SUM(COUNTIFS(人员调整计划!$G:$G,$A4,人员调整计划!$AD:$AD,"理工",人员调整计划!BT:BT,{"在编","调岗","新增","优化"}))/M4} -> 0.020833333 | N16: {=SUM(COUNTIFS(人员调整计划!$G:$G,$A4,人员调整计划!$AD:$AD,"理工",人员调整计划!BU:BU,{"在编","调岗","新增","优化"}))/N4} -> 0.020833333 | O16: {=SUM(COUNTIFS(人员调整计划!$G:$G,$A4,人员调整计划!$AD:$AD,"理工",人员调整计划!BV:BV,{"在编","调岗","新增","优化"}))/O4} -> 0.020833333 | P16: {=SUM(COUNTIFS(人员调整计划!$G:$G,$A4,人员调整计划!$AD:$AD,"理工",人员调整计划!BW:BW,{"在编","调岗","新增","优化"}))/P4} -> 0.020833333
C17: 数字化 BP-人数 | D17: =P17 -> 0.125 | E17: {=SUM(COUNTIFS(人员调整计划!$G:$G,$A4,人员调整计划!$AD:$AD,"数字化",人员调整计划!BL:BL,{"在编","调岗","新增","优化"}))/E4} -> 0.038461538 | F17: {=SUM(COUNTIFS(人员调整计划!$G:$G,$A4,人员调整计划!$AD:$AD,"数字化",人员调整计划!BM:BM,{"在编","调岗","新增","优化"}))/F4} -> 0.038461538 | G17: {=SUM(COUNTIFS(人员调整计划!$G:$G,$A4,人员调整计划!$AD:$AD,"数字化",人员调整计划!BN:BN,{"在编","调岗","新增","优化"}))/G4} -> 0.038461538 | H17: {=SUM(COUNTIFS(人员调整计划!$G:$G,$A4,人员调整计划!$AD:$AD,"数字化",人员调整计划!BO:BO,{"在编","调岗","新增","优化"}))/H4} -> 0.070175439 | I17: {=SUM(COUNTIFS(人员调整计划!$G:$G,$A4,人员调整计划!$AD:$AD,"数字化",人员调整计划!BP:BP,{"在编","调岗","新增","优化"}))/I4} -> 0.11111111 | J17: {=SUM(COUNTIFS(人员调整计划!$G:$G,$A4,人员调整计划!$AD:$AD,"数字化",人员调整计划!BQ:BQ,{"在编","调岗","新增","优化"}))/J4} -> 0.11864407 | K17: {=SUM(COUNTIFS(人员调整计划!$G:$G,$A4,人员调整计划!$AD:$AD,"数字化",人员调整计划!BR:BR,{"在编","调岗","新增","优化"}))/K4} -> 0.10714286 | L17: {=SUM(COUNTIFS(人员调整计划!$G:$G,$A4,人员调整计划!$AD:$AD,"数字化",人员调整计划!BS:BS,{"在编","调岗","新增","优化"}))/L4} -> 0.125 | M17: {=SUM(COUNTIFS(人员调整计划!$G:$G,$A4,人员调整计划!$AD:$AD,"数字化",人员调整计划!BT:BT,{"在编","调岗","新增","优化"}))/M4} -> 0.125 | N17: {=SUM(COUNTIFS(人员调整计划!$G:$G,$A4,人员调整计划!$AD:$AD,"数字化",人员调整计划!BU:BU,{"在编","调岗","新增","优化"}))/N4} -> 0.125 | O17: {=SUM(COUNTIFS(人员调整计划!$G:$G,$A4,人员调整计划!$AD:$AD,"数字化",人员调整计划!BV:BV,{"在编","调岗","新增","优化"}))/O4} -> 0.125 | P17: {=SUM(COUNTIFS(人员调整计划!$G:$G,$A4,人员调整计划!$AD:$AD,"数字化",人员调整计划!BW:BW,{"在编","调岗","新增","优化"}))/P4} -> 0.125
C18: 英语 BP-人数 | D18: =P18 -> 0 | E18: {=SUM(COUNTIFS(人员调整计划!$G:$G,$A4,人员调整计划!$AD:$AD,"英语",人员调整计划!BL:BL,{"在编","调岗","新增","优化"}))/E4} -> 0.019230769 | F18: {=SUM(COUNTIFS(人员调整计划!$G:$G,$A4,人员调整计划!$AD:$AD,"英语",人员调整计划!BM:BM,{"在编","调岗","新增","优化"}))/F4} -> 0.019230769 | G18: {=SUM(COUNTIFS(人员调整计划!$G:$G,$A4,人员调整计划!$AD:$AD,"英语",人员调整计划!BN:BN,{"在编","调岗","新增","优化"}))/G4} -> 0.019230769 | H18: {=SUM(COUNTIFS(人员调整计划!$G:$G,$A4,人员调整计划!$AD:$AD,"英语",人员调整计划!BO:BO,{"在编","调岗","新增","优化"}))/H4} -> 0.01754386 | I18: {=SUM(COUNTIFS(人员调整计划!$G:$G,$A4,人员调整计划!$AD:$AD,"英语",人员调整计划!BP:BP,{"在编","调岗","新增","优化"}))/I4} -> 0.015873016 | J18: {=SUM(COUNTIFS(人员调整计划!$G:$G,$A4,人员调整计划!$AD:$AD,"英语",人员调整计划!BQ:BQ,{"在编","调岗","新增","优化"}))/J4} -> 0 | K18: {=SUM(COUNTIFS(人员调整计划!$G:$G,$A4,人员调整计划!$AD:$AD,"英语",人员调整计划!BR:BR,{"在编","调岗","新增","优化"}))/K4} -> 0 | L18: {=SUM(COUNTIFS(人员调整计划!$G:$G,$A4,人员调整计划!$AD:$AD,"英语",人员调整计划!BS:BS,{"在编","调岗","新增","优化"}))/L4} -> 0 | M18: {=SUM(COUNTIFS(人员调整计划!$G:$G,$A4,人员调整计划!$AD:$AD,"英语",人员调整计划!BT:BT,{"在编","调岗","新增","优化"}))/M4} -> 0 | N18: {=SUM(COUNTIFS(人员调整计划!$G:$G,$A4,人员调整计划!$AD:$AD,"英语",人员调整计划!BU:BU,{"在编","调岗","新增","优化"}))/N4} -> 0 | O18: {=SUM(COUNTIFS(人员调整计划!$G:$G,$A4,人员调整计划!$AD:$AD,"英语",人员调整计划!BV:BV,{"在编","调岗","新增","优化"}))/O4} -> 0 | P18: {=SUM(COUNTIFS(人员调整计划!$G:$G,$A4,人员调整计划!$AD:$AD,"英语",人员调整计划!BW:BW,{"在编","调岗","新增","优化"}))/P4} -> 0

Sheet 人员调整计划
A1: 后勤部人力资源调整计划
A2: 编号 | B2: 姓名 | C2: 处级名称 | D2: 部门号码 | E2: 部门名称 | F2: 职务 | G2: 合并后部门 | H2: 调整后部门 | I2: 状态 | J2: 到职日期 | K2: 离职日期 | L2: 申请离职日期 | M2: 备注 | N2: 临工种类标志 | O2: 政治面貌 | P2: 没入职操作日期 | Q2: 离职操作日期 | R2: 联系电话 | S2: 性别 | T2: 户口所在地 | U2: 日历方案 | V2: 身份证号码 | W2: 婚姻状态 | X2: 地址 | Y2: 学历 | Z2: 专业 | AA2: 毕业学校 | AB2: 学校等级 | AC2: 专业岗匹配 | AD2: 六边形BP | AE2: 身份证有效期 | AF2: 生日 | AG2: 农历生日 | AH2: 年龄 | AI2: 民族 | AJ2: 离职原因 | AK2: 异动岗位 | AL2: 合同开始日 | AM2: 合同到期日 | AN2: 薪资帐套 | AO2: 民族 | AP2: 人员性质 | AQ2: 合同开始日 | AR2: 合同到期日 | AS2: 薪资帐套 | AT2: 籍贯地区 | AU2: 入职年份 | AV2: 试用期 | AW2: 转正日期 | AX2: 工龄 | AY2: 个人履历 | AZ2: 过往病史 | BA2: 有无违法犯罪记录 | BB2: 卡号 | BC2: 中介 | BD2: 职等 | BE2: 级别 | BF2: 照片 | BG2: 籍贯 | BH2: 是否加入b帐 | BI2: 是否购买社保 | BJ2: 开始购买社保日期 | BK2: 结束购买社保日期 | BL2: 1月 | BM2: 2月 | BN2: 3月 | BO2: 4月 | BP2: 5月 | BQ2: 6月 | BR2: 7月 | BS2: 8月 | BT2: 9月 | BU2: 10月 | BV2: 11月 | BW2: 12月
A3: 22735 | B3: 李兵 | C3: 部长 | D3: 001017 | E3: 后勤部 | F3: 部长 | G3: 后勤部 | H3: 后勤部 | I3: 在职 | J3: 44419 | M3: 2025年10月转回宝士；2024年7月入江西天骏江门分公司；2024年5月调其他外聘；2022年12月转工程项目部 | O3: 群众 | R3: 18022979628 | S3: 男 | T3: 山西省运城市盐湖区龙居镇下张耿村一组 | V3: 142701198807162136 | W3: 已婚 | X3: 广东省江门市江海区碧桂园江海碧桂园芷兰湾6街4栋3106 | Y3: 高中 | Z3: / | AA3: 龙居中学 | AB3: 高中 | AC3: #N/A | AE3: 49857 | AF3: 32382 | AH3: 37 | AI3: 汉 | AL3: 44215 | AM3: 44214 | AO3: 汉 | AP3: 直接 | AQ3: 44215 | AR3: 44214 | AT3: 山西运城 | AU3: 2021 | AV3: 3 | AW3: 44305 | AX3: 5 | BL3: 在编 | BM3: 在编 | BN3: 在编 | BO3: 在编 | BP3: 在编 | BQ3: 在编 | BR3: 在编 | BS3: 在编 | BT3: 在编 | BU3: 在编 | BV3: 在编 | BW3: 在编
A4: 26872 | B4: 曾嘉惠 | C4: 文控 | D4: 001017 | E4: 后勤部 | F4: 文控 | G4: 后勤部 | H4: 后勤部 | I4: 在职 | J4: 44736 | O4: 群众 | R4: 13286133727 | S4: 女 | T4: 广东省江门市江海区礼乐武东东和里101号 | V4: 440702200008231524 | W4: 未婚 | X4: 广东省江门市江海区礼乐武东东和里101号 | Y4: 大专 | Z4: 园林工程技术 | AA4: 广东环境保护工程职业学院 | AB4: 大专 | AC4: 间接 | AE4: 47631 | AF4: 36761 | AH4: 25 | AI4: 汉 | AL4: 44585 | AM4: 44584 | AN4: 月薪（没有伙食津贴） | AO4: 汉 | AP4: 直接 | AQ4: 44585 | AR4: 44584 | AS4: 月薪（没有伙食津贴） | AT4: 广东江门 | AU4: 2022 | AV4: 3 | AW4: 44675 | AX4: 4 | BL4: 在编 | BM4: 在编 | BN4: 在编 | BO4: 在编 | BP4: 在编 | BQ4: 在编 | BR4: 在编 | BS4: 在编 | BT4: 在编 | BU4: 在编 | BV4: 在编 | BW4: 在编
A5: 36926 | B5: 沈云杰 | C5: 安保处 | D5: 001017 | E5: 后勤部 | F5: 副主管 | G5: 后勤部 | H5: 后勤部 | I5: 在职 | J5: 45770 | O5: 群众 | R5: 13126272001 | S5: 男 | T5: 江苏省兴化市张郭镇南桥村南西惠民路西1巷14号 | V5: 321281199409247953 | W5: 已婚 | X5: 广东省江门市江海区碧桂园 | Y5: 大专 | Z5: 物流管理 | AA5: 江苏农牧科技职业学院 | AB5: 大专 | AC5: 直接 | AE5: 47656 | AF5: 27492 | AH5: 31 | AI5: 汉 | AL5: 45770 | AM5: 45769 | AN5: 月薪（没有伙食津贴） | AO5: 汉 | AP5: 直接 | AQ5: 45770 | AR5: 45769 | AS5: 月薪（没有伙食津贴） | AT5: 江苏泰州 | AU5: 2025 | AV5: 3 | AW5: 45861 | AX5: 0 | BL5: 在编 | BM5: 在编 | BN5: 在编 | BO5: 在编 | BP5: 在编 | BQ5: 在编 | BR5: 在编 | BS5: 在编 | BT5: 在编 | BU5: 在编 | BV5: 在编 | BW5: 在编
A6: 25030 | B6: 刘家华 | C6: 安保处 | D6: 001017 | E6: 后勤部 | F6: 保安 | G6: 后勤部 | H6: 后勤部 | I6: 在职 | J6: 44419 | M6: 2025.9.10由行政部异动至后勤部 | O6: 群众 | R6: 15089846868 | S6: 男 | T6: 广东省南雄市百顺镇百顺村委会老屋村27号 | V6: 440223198302102015 | W6: 已婚 | X6: 江门市江海区麻园麻二高地里四巷四号 | Y6: 高中 | Z6: / | AA6: 南雄中学 | AB6: 高中 | AC6: 直接 | AE6: 49666 | AF6: 29214 | AH6: 43 | AI6: 汉 | AL6: 44419 | AM6: 44783 | AN6: 月薪（没有伙食津贴） | AO6: 汉 | AP6: 直接 | AQ6: 44419 | AR6: 44783 | AS6: 月薪（没有伙食津贴） | AT6: 广东南雄 | AU6: 2021 | AV6: 3 | AW6: 44511 | AX6: 4 | BL6: 在编 | BM6: 在编 | BN6: 在编 | BO6: 在编 | BP6: 在编 | BQ6: 在编 | BR6: 在编 | BS6: 在编 | BT6: 在编 | BU6: 在编 | BV6: 在编 | BW6: 在编
A7: 28945 | B7: 黄健波 | C7: 安保处 | D7: 001017 | E7: 后勤部 | F7: 保安 | G7: 后勤部 | H7: 后勤部 | I7: 在职 | J7: 44736 | M7: 2025.9.10由行政部异动至后勤部 | O7: 群众 | R7: 13106955988 | S7: 男 | T7: 广东省江门市蓬江区水南凤阳里98号702 | V7: 440711198903074218 | W7: 已婚 | X7: 广东省江门市蓬江区水南凤阳里98号702 | Y7: 中专 | Z7: 钳工数控 | AA7: 江门市高级技工学校 | AB7: 中专 | AC7: 直接 | AE7: 52517 | AF7: 32971 | AH7: 37 | AI7: 汉 | AL7: 44736 | AM7: 44735 | AN7: 月薪（没有伙食津贴） | AO7: 汉 | AP7: 直接 | AQ7: 44736 | AR7: 44735 | AS7: 月薪（没有伙食津贴） | AT7: 广东江门 | AU7: 2022 | AV7: 3 | AW7: 44828 | AX7: 3 | BL7: 在编 | BM7: 在编 | BN7: 在编 | BO7: 在编 | BP7: 优化
A8: 29185 | B8: 陶瑞麟 | C8: 安保处 | D8: 001017 | E8: 后勤部 | F8: 保安 | G8: 后勤部 | H8: 后勤部 | I8: 在职 | J8: 45700 | M8: 2025年9月15日由行政部异动至后勤部；2025年8月人员调整通知：保安队长调整为保安 | O8: 共青团员 | R8: 17520140524 | S8: 男 | T8: 湖北省谷城县城关镇粉阳路98号 | V8: 420625199405240053 | W8: 已婚 | X8: 广东省江门市蓬江区白沙街道丰盛里604 | Y8: 高中 | Z8: / | AA8: 谷城县第三高级中学 | AB8: 高中 | AC8: 直接 | AE8: 52431 | AF8: 29773 | AH8: 31 | AI8: 汉 | AL8: 44795 | AM8: 44794 | AN8: 月薪（没有伙食津贴） | AO8: 汉 | AP8: 直接 | AQ8: 44795 | AR8: 44794 | AS8: 月薪（没有伙食津贴） | AT8: 湖北谷城县 | AU8: 2022 | AV8: 3 | AW8: 44887 | AX8: 3 | BL8: 在编 | BM8: 在编 | BN8: 在编 | BO8: 优化
A9: 34849 | B9: 唐银龙 | C9: 安保处 | D9: 001017 | E9: 后勤部 | F9: 保安 | G9: 后勤部 | H9: 后勤部 | I9: 在职 | J9: 45715 | O9: 群众 | R9: 15875093787 | S9: 男 | T9: 四川省宜宾县喜捷镇新民村严湾组375号 | V9: 511521199708080431 | W9: 未婚 | X9: 广东省江门市江海区外海街道石塘新村3栋之3 301 | Y9: 中专 | Z9: 营销与服装 | AA9: 江门技师学院 | AB9: 中专 | AC9: 直接 | AE9: 46378 | AF9: 30125 | AH9: 28 | AI9: 汉 | AL9: 45579 | AM9: 45578 | AN9: 月薪（没有伙食津贴） | AO9: 汉 | AP9: 直接 | AQ9: 45579 | AR9: 45578 | AS9: 月薪（没有伙食津贴） | AT9: 四川宜宾 | AU9: 2024 | AV9: 3 | AW9: 45671 | AX9: 1 | BL9: 在编 | BM9: 在编 | BN9: 在编 | BO9: 在编 | BP9: 在编 | BQ9: 在编 | BR9: 在编 | BS9: 在编 | BT9: 在编 | BU9: 在编 | BV9: 在编 | BW9: 在编
A10: 35339 | B10: 贺一文 | C10: 安保处 | D10: 001017 | E10: 后勤部 | F10: 保安 | G10: 后勤部 | H10: 后勤部 | I10: 在职 | J10: 45603 | O10: 共青团员 | R10: 13135019550 | S10: 男 | T10: 湖南省湘潭县谭家山镇红星村泉塘组 | V10: 430321199409240034 | W10: 未婚 | X10: 广东省江门市江海区外海街道中东村黄字里16巷8号101 | Y10: 中专 | Z10: 计算机 | AA10: 湘潭县一职 | AB10: 中专 | AC10: 直接 | AE10: 52675 | AF10: 32042 | AH10: 31 | AI10: 汉 | AL10: 45603 | AM10: 45602 | AN10: 月薪（没有伙食津贴） | AO10: 汉 | AP10: 直接 | AQ10: 45603 | AR10: 45602 | AS10: 月薪（没有伙食津贴） | AT10: 湖南湘潭 | AU10: 2024 | AV10: 3 | AW10: 45695 | AX10: 1 | BL10: 在编 | BM10: 在编 | BN10: 在编 | BO10: 在编 | BP10: 在编 | BQ10: 在编 | BR10: 在编 | BS10: 在编 | BT10: 在编 | BU10: 在编 | BV10: 在编 | BW10: 在编
A11: 36409 | B11: 李俊岗 | C11: 安保处 | D11: 001017 | E11: 后勤部 | F11: 保安 | G11: 后勤部 | H11: 后勤部 | I11: 在职 | J11: 45770 | O11: 群众 | R11: 17722951101 | S11: 男 | T11: 云南省红河哈尼族彝族自治州弥勒市巡检司镇宣武村委会宣武寨村70号 | V11: 532526199904201719 | W11: 未婚 | X11: 广东省江门市高新区江海嘉美公寓C幢403 | Y11: 高中 | Z11: / | AA11: 弥勒市第二中学 | AB11: 高中 | AC11: 直接 | AE11: 48982 | AF11: 31021 | AH11: 26 | AI11: 汉 | AL11: 45700 | AM11: 45699 | AN11: 月薪（没有伙食津贴） | AO11: 汉 | AP11: 直接 | AQ11: 45700 | AR11: 45699 | AS11: 月薪（没有伙食津贴） | AT11: 云南弥勒 | AU11: 2025 | AV11: 3 | AW11: 45789 | AX11: 1 | BL11: 在编 | BM11: 在编 | BN11: 在编 | BO11: 在编 | BP11: 在编 | BQ11: 在编 | BR11: 在编 | BS11: 在编 | BT11: 在编 | BU11: 在编 | BV11: 在编 | BW11: 在编
A12: 36651 | B12: 罗伟 | C12: 安保处 | D12: 001017 | E12: 后勤部 | F12: 保安 | G12: 后勤部 | H12: 后勤部 | I12: 在职 | J12: 45915 | O12: 群众 | R12: 17520315652 | S12: 男 | T12: 贵州省德江县长堡镇灯塔村小坳组 | V12: 522227200310255617 | W12: 未婚 | X12: 广东省江门市高新区东宁路101号万利公寓206 | Y12: 中专 | Z12: 烹饪（中式烹调） | AA12: 江门市技师学院 | AB12: 中专 | AC12: 直接 | AE12: 48689 | AF12: 30966 | AH12: 22 | AI12: 土家 | AL12: 45715 | AM12: 45714 | AN12: 月薪（没有伙食津贴） | AO12: 土家 | AP12: 直接 | AQ12: 45715 | AR12: 45714 | AS12: 月薪（没有伙食津贴） | AT12: 贵州铜仁 | AU12: 2025 | AV12: 3 | AW12: 45804 | AX12: 1 | BL12: 在编 | BM12: 在编 | BN12: 在编 | BO12: 在编 | BP12: 在编 | BQ12: 在编 | BR12: 在编 | BS12: 在编 | BT12: 在编 | BU12: 在编 | BV12: 在编 | BW12: 在编
A13: 36684 | B13: 邝凌鹏 | C13: 安保处 | D13: 001017 | E13: 后勤部 | F13: 保安 | G13: 后勤部 | H13: 后勤部 | I13: 在职 | J13: 45720 | O13: 共青团员 | R13: 15398848652 | S13: 男 | T13: 广东省乐昌市三溪镇车头园村委会偏石组2号 | V13: 440281200302265213 | W13: 未婚 | X13: 广东省江门市江海区外海街道西安里七巷7号 | Y13: 中专 | Z13: 汽车运用与维修 | AA13: 韶关市振华中等职业学校 | AB13: 中专 | AC13: 直接 | AE13: 47723 | AF13: 29236 | AH13: 23 | AI13: 汉 | AL13: 45720 | AM13: 45719 | AN13: 月薪（没有伙食津贴） | AO13: 汉 | AP13: 直接 | AQ13: 45720 | AR13: 45719 | AS13: 月薪（没有伙食津贴） | AT13: 广东乐昌 | AU13: 2025 | AV13: 3 | AW13: 45812 | AX13: 1 | BL13: 在编 | BM13: 在编 | BN13: 在编 | BO13: 在编 | BP13: 在编 | BQ13: 在编 | BR13: 在编 | BS13: 在编 | BT13: 在编 | BU13: 在编 | BV13: 在编 | BW13: 在编
A14: 37607 | B14: 职季魁 | C14: 安保处 | D14: 001017 | E14: 后勤部 | F14: 保安 | G14: 后勤部 | H14: 后勤部 | I14: 在职 | J14: 46058 | O14: 中共党员 | R14: 13322915979 | S14: 男 | T14: 河南省获嘉县冯庄镇职王村社区东区纬二路5号 | V14: 410724199610055014 | W14: 未婚 | X14: 广东省江门市江海区外海街道海逸星宸星钻轩一栋504 | Y14: 高中 | Z14: / | AA14: 获嘉县高级中学 | AB14: 高中 | AC14: 直接 | AE14: 47377 | AF14: 35700 | AH14: 29 | AI14: 汉 | AL14: 45912 | AM14: 45911 | AN14: 月薪（没有伙食津贴） | AO14: 汉 | AP14: 直接 | AQ14: 45912 | AR14: 45911 | AS14: 月薪（没有伙食津贴） | AT14: 河南获嘉县 | AU14: 2025 | AV14: 3 | AW14: 46003 | AX14: 0 | BL14: 在编 | BM14: 在编 | BN14: 在编 | BO14: 在编 | BP14: 在编 | BQ14: 在编 | BR14: 在编 | BS14: 在编 | BT14: 在编 | BU14: 在编 | BV14: 在编 | BW14: 在编
A15: 37938 | B15: 伍康福 | C15: 安保处 | D15: 001017 | E15: 后勤部 | F15: 保安 | G15: 后勤部 | H15: 后勤部 | I15: 在职 | J15: 45964 | O15: 群众 | R15: 15658885717 | S15: 男 | T15: 广西北流市石窝镇煌炉村六粟组22-1号 | V15: 450981199906085031 | W15: 未婚 | X15: 广东省江门市蓬江区杜阮绿景苑 | Y15: 中专 | Z15: 汽修运用与维修 | AA15: 江门市工贸职业技术学校 | AB15: 中专 | AC15: 直接 | AE15: 46218 | AF15: 32711 | AH15: 26 | AI15: 汉 | AL15: 45964 | AM15: 45963 | AN15: 月薪（没有伙食津贴） | AO15: 汉 | AP15: 直接 | AQ15: 45964 | AR15: 45963 | AS15: 月薪（没有伙食津贴） | AT15: 广西北流 | AU15: 2025 | AV15: 3 | AW15: 46056 | AX15: 0 | BL15: 在编 | BM15: 在编 | BN15: 在编 | BO15: 在编 | BP15: 在编 | BQ15: 在编 | BR15: 在编 | BS15: 在编 | BT15: 在编 | BU15: 在编 | BV15: 在编 | BW15: 在编
A16: 38368 | B16: 戴琛 | C16: 安保处 | D16: 001017 | E16: 后勤部 | F16: 保安 | G16: 后勤部 | H16: 后勤部 | I16: 在职 | J16: 46002 | O16: 中共党员 | R16: 13042963223 | S16: 男 | T16: 广东省雷州市雷城街道广朝南街9589号 | V16: 440882199908180015 | W16: 未婚 | Y16: 大专 | Z16: 计算机应用 | AA16: 广东南方职业学院 | AB16: 大专 | AC16: 直接 | AE16: 48101 | AF16: 37184 | AH16: 26 | AI16: 汉 | AL16: 46002 | AM16: 46001 | AN16: 月薪（没有伙食津贴） | AO16: 汉 | AP16: 直接 | AQ16: 46002 | AR16: 46001 | AS16: 月薪（没有伙食津贴） | AT16: 广东湛江 | AU16: 2025 | AV16: 3 | AW16: 46092 | AX16: 0 | BL16: 在编 | BM16: 在编 | BN16: 在编 | BO16: 在编 | BP16: 在编 | BQ16: 在编 | BR16: 在编 | BS16: 在编 | BT16: 在编 | BU16: 在编 | BV16: 在编 | BW16: 在编
A17: 39072 | B17: 王晨光 | C17: 安保处 | D17: 001017 | E17: 后勤部 | F17: 保安 | G17: 后勤部 | H17: 后勤部 | I17: 在职 | J17: 46058 | O17: 群众 | R17: 13135738600 | S17: 男 | T17: 湖北省广水市应山办事处三里河街特3号 | V17: 411424200111126631 | W17: 未婚 | X17: 广东省江门市常只街四巷 | Y17: 高中 | Z17: / | AA17: 拓城二中 | AB17: 高中 | AC17: 直接 | AE17: 48732 | AF17: 33256 | AH17: 24 | AI17: 汉 | AL17: 46058 | AM17: 46057 | AN17: 月薪（没有伙食津贴） | AO17: 汉 | AP17: 直接 | AQ17: 46058 | AR17: 46057 | AS17: 月薪（没有伙食津贴） | AT17: 河南商丘 | AU17: 2026 | AV17: 3 | AW17: 46147 | AX17: 0 | BL17: 在编 | BM17: 在编 | BN17: 在编 | BO17: 在编 | BP17: 在编 | BQ17: 在编 | BR17: 在编 | BS17: 在编 | BT17: 在编 | BU17: 在编 | BV17: 在编 | BW17: 在编
A18: 23386 | B18: 赵雅茵 | C18: 专项事务监察处 | D18: 001017 | E18: 后勤部 | F18: 主管 | G18: 后勤部 | H18: 后勤部 | I18: 在职 | J18: 44256 | M18: 2023年4月总裁办调至集采处；2023年2月1日由秘书处调至总裁办；2022年11月16日由集采处集采物控员调至秘书处总裁办秘书；21年4月调整到工程项目部；2021年10月25日调至集采处 | O18: 中共党员 | R18: 18802589602 | S18: 女 | T18: 广东省江门市新会区三江镇联和塘上里86号 | V18: 440782199806195325 | W18: 已婚 | X18: 江门市江海区天鹅湾庄园苑12幢之一1403 | Y18: 大专 | Z18: 会计 | AA18: 广东南方职业学院 | AB18: 大专 | AC18: 直接 | AE18: 53144 | AF18: 35598 | AH18: 27 | AI18: 汉 | AL18: 44256 | AM18: 44620 | AN18: 月薪（没有伙食津贴） | AO18: 汉 | AP18: 直接 | AQ18: 44256 | AR18: 44620 | AS18: 月薪（没有伙食津贴） | AT18: 广东江门 | AU18: 2021 | AV18: 3 | AW18: 44348 | AX18: 5 | BL18: 在编 | BM18: 在编 | BN18: 在编 | BO18: 在编 | BP18: 在编 | BQ18: 在编 | BR18: 在编 | BS18: 在编 | BT18: 在编 | BU18: 在编 | BV18: 在编 | BW18: 在编
A19: 15159 | B19: 黄志伟 | C19: 专项事务监察处 | D19: 001017 | E19: 后勤部 | F19: 代副主管 | G19: 后勤部 | H19: 后勤部 | I19: 在职 | J19: 43794 | M19: 2023年10月17日技术部异动至工程项目部；2023年2月27日工程部调为结构工程部；2022年9月14日工程部调至工程综合组。2022年6月调至工程部工程组；2022年4月BOM组调至结构部工程组 | O19: 群众 | R19: 17376911160 | S19: 男 | T19: 广东省揭阳市揭东区锡场镇东仓村大丘田北二 | V19: 445221199612024936 | W19: 未婚 | X19: 广东省江门市高新区东宁路101号万利公寓316 | Y19: 大专 | Z19: 机械设计与制造 | AA19: 江门职业技术学院 | AB19: 大专 | AC19: 直接 | AD19: 理工 | AE19: 46578 | AF19: 36944 | AH19: 29 | AI19: 汉 | AL19: 43794 | AM19: 43791 | AN19: 月薪（没有伙食津贴） | AO19: 汉 | AP19: 直接 | AQ19: 43794 | AR19: 43791 | AS19: 月薪（没有伙食津贴） | AT19: 广东揭阳 | AU19: 2019 | AV19: 3 | AW19: 43884 | AX19: 6 | BL19: 在编 | BM19: 在编 | BN19: 在编 | BO19: 在编 | BP19: 在编 | BQ19: 在编 | BR19: 在编 | BS19: 在编 | BT19: 在编 | BU19: 在编 | BV19: 在编 | BW19: 在编
A20: 37562 | B20: 刁德华 | C20: 专项事务监察处 | D20: 001017 | E20: 后勤部 | F20: 食堂监察组长 | G20: 后勤部 | H20: 后勤部 | I20: 在职 | J20: 45860 | O20: 群众 | R20: 17507504504 | S20: 男 | T20: 广西武宣县东乡镇金岗村民委金榜村5队116号 | V20: 452225199705174217 | W20: 未婚 | X20: 江门市蓬江区育德东苑15栋603号 | Y20: 大专 | Z20: 广告 | AA20: 国家开放大学 | AB20: 大专 | AC20: 不对口 | AE20: 48223 | AF20: 37770 | AH20: 28 | AI20: 汉 | AL20: 45860 | AM20: 45859 | AN20: 月薪（没有伙食津贴） | AO20: 汉 | AP20: 直接 | AQ20: 45860 | AR20: 45859 | AS20: 月薪（没有伙食津贴） | AT20: 广西武宣 | AU20: 2025 | AV20: 3 | AW20: 45952 | AX20: 0 | BL20: 在编 | BM20: 在编 | BN20: 在编 | BO20: 在编 | BP20: 在编 | BQ20: 在编 | BR20: 在编 | BS20: 在编 | BT20: 在编 | BU20: 在编 | BV20: 在编 | BW20: 在编
A21: 37294 | B21: 张苑桦 | C21: 专项事务监察处 | D21: 001017 | E21: 后勤部 | F21: 宿舍监察专员 | G21: 后勤部 | H21: 后勤部 | I21: 在职 | J21: 45846 | M21: 2025年11月18日由行政部异动至后勤部 | O21: 群众 | R21: 13422692587 | S21: 女 | T21: 广东省江门市江海区江南江南路7号603 | V21: 440702200308050928 | W21: 未婚 | X21: 广东省江门市江海区翠园里10号 | Y21: 本科 | Z21: 汉语言文学 | AA21: 五邑大学 | AB21: 二本 | AC21: 不对口 | AE21: 48721 | AF21: 33965 | AH21: 22 | AI21: 汉 | AL21: 45846 | AM21: 45845 | AN21: 月薪（没有伙食津贴） | AO21: 汉 | AP21: 直接 | AQ21: 45846 | AR21: 45845 | AS21: 月薪（没有伙食津贴） | AT21: 广东江门 | AU21: 2025 | AV21: 3 | AW21: 45938 | AX21: 0 | BL21: 在编 | BM21: 在编 | BN21: 在编 | BO21: 在编 | BP21: 在编 | BQ21: 在编 | BR21: 在编 | BS21: 在编 | BT21: 在编 | BU21: 在编 | BV21: 在编 | BW21: 在编
A22: 38041 | B22: 区颖芝 | C22: 专项事务监察处 | D22: 001017 | E22: 后勤部 | F22: 食堂监察专员 | G22: 后勤部 | H22: 后勤部 | I22: 在职 | J22: 45979 | O22: 群众 | R22: 17361712072 | S22: 女 | T22: 广东省江门市江海区礼乐威西永贤里43号 | V22: 440702200109151523 | W22: 未婚 | X22: 广东省江门市江海区礼乐威西永贤里43号 | Y22: 本科 | Z22: 物联网工程 | AA22: 南京信息工程大学滨江学院 | AB22: 二本 | AC22: 不对口 | AE22: 48389 | AF22: 32845 | AH22: 24 | AI22: 汉 | AL22: 45979 | AM22: 45978 | AN22: 月薪（没有伙食津贴） | AO22: 汉 | AP22: 直接 | AQ22: 45979 | AR22: 45978 | AS22: 月薪（没有伙食津贴） | AT22: 广东江门 | AU22: 2025 | AV22: 3 | AW22: 46071 | AX22: 0 | BL22: 在编 | BM22: 在编 | BN22: 在编 | BO22: 在编 | BP22: 在编 | BQ22: 在编 | BR22: 在编 | BS22: 在编 | BT22: 在编 | BU22: 在编 | BV22: 在编 | BW22: 在编
A23: 31586 | B23: 蔡国喜 | C23: 专项事务监察处 | D23: 001017 | E23: 后勤部 | F23: 保洁组组长 | G23: 后勤部 | H23: 后勤部 | I23: 在职 | J23: 45248 | O23: 群众 | R23: 13375965660 | S23: 男 | T23: 贵州省印江土家族苗族自治县洋溪镇新阳村老寨组 | V23: 522226199706162810 | W23: 未婚 | X23: 广东省江门市高新区东宁路101号万利公寓221 | Y23: 大专 | Z23: 国际邮轮乘务管理 | AA23: 江苏海事职业技术学院 | AB23: 大专 | AC23: 不对口 | AE23: 52467 | AF23: 34898 | AH23: 28 | AI23: 汉 | AL23: 45248 | AM23: 45247 | AN23: 月薪（没有伙食津贴） | AO23: 汉 | AP23: 直接 | AQ23: 45248 | AR23: 45247 | AS23: 月薪（没有伙食津贴） | AT23: 贵州铜仁 | AU23: 2023 | AV23: 3 | AW23: 45340 | AX23: 2 | BL23: 在编 | BM23: 在编 | BN23: 在编 | BO23: 在编 | BP23: 在编 | BQ23: 在编 | BR23: 在编 | BS23: 在编 | BT23: 在编 | BU23: 在编 | BV23: 在编 | BW23: 在编
A24: 29496 | B24: 林秀兰 | C24: 保洁 | D24: 001017 | E24: 后勤部 | F24: 保洁员 | G24: 后勤部 | H24: 后勤部 | I24: 在职 | J24: 44912 | M24: 2025年10月18日由行政部异动至后勤部 | O24: 群众 | R24: 15913645957 | S24: 女 | T24: 广东省江门市江海区武东茂隆里223号 | V24: 440702197912251561 | W24: 已婚 | X24: 广东省江门市江海区武东茂隆里223号 | Y24: 初中 | Z24: / | AA24: 礼乐中学 | AB24: 初中 | AC24: 直接 | AE24: 46348 | AF24: 26649 | AH24: 46 | AI24: 汉 | AL24: 44912 | AM24: 44911 | AN24: 月薪（没有伙食津贴） | AO24: 汉 | AP24: 直接 | AQ24: 44912 | AR24: 44911 | AS24: 月薪（没有伙食津贴） | AT24: 广东江门 | AU24: 2022 | AV24: 3 | AW24: 45002 | AX24: 3 | BL24: 在编 | BM24: 在编 | BN24: 在编 | BO24: 在编 | BP24: 在编 | BQ24: 在编 | BR24: 优化
A25: 34407 | B25: 梁世杰 | C25: 保洁 | D25: 001017 | E25: 后勤部 | F25: 户外环境卫生监察专员 | G25: 后勤部 | H25: 生产部 | I25: 在职 | J25: 45429 | M25: 江西外包人员 | O25: 群众 | R25: 18718961051 | S25: 男 | T25: 广东省罗定市太平镇太西村委石豆4号 | V25: 445381199004080872 | W25: 已婚 | X25: 广东省江门市高新区东宁路101号万利公寓225 | Y25: 初中 | Z25: / | AA25: 太平中学 | AB25: 初中 | AC25: 不对口 | AE25: 51807 | AF25: 30873 | AH25: 35 | AI25: 汉 | AL25: 45428 | AM25: 45427 | AN25: 月薪（没有伙食津贴） | AO25: 汉 | AP25: 直接 | AQ25: 45428 | AR25: 45427 | AS25: 月薪（没有伙食津贴） | AT25: 广东罗定 | AU25: 2024 | AV25: 3 | AW25: 45520 | AX25: 1 | BL25: 在编 | BM25: 在编 | BN25: 在编 | BO25: 在编 | BP25: 在编 | BQ25: 在编 | BR25: 调岗
A26: 35803 | B26: 陈玉珍 | C26: 保洁 | D26: 001017 | E26: 后勤部 | F26: 保洁员 | G26: 后勤部 | H26: 后勤部 | I26: 在职 | J26: 45659 | O26: 群众 | R26: 13630471086 | S26: 女 | T26: 广东省德庆县九市镇九市村委会山顶村024号 | V26: 441226198107064025 | W26: 已婚 | X26: 广东省江门市江海区麻园麻三环溪新村51号302 | Y26: 初中 | Z26: / | AA26: 九市中学 | AB26: 初中 | AC26: 直接 | AE26: 51704 | AF26: 30462 | AH26: 44 | AI26: 汉 | AL26: 45659 | AM26: 45658 | AN26: 月薪（没有伙食津贴） | AO26: 汉 | AP26: 直接 | AQ26: 45659 | AR26: 45658 | AS26: 月薪（没有伙食津贴） | AT26: 广东肇庆 | AU26: 2025 | AV26: 3 | AW26: 45749 | AX26: 1 | BL26: 在编 | BM26: 在编 | BN26: 在编 | BO26: 在编 | BP26: 在编 | BQ26: 在编 | BR26: 优化
A27: 36822 | B27: 罗艮英 | C27: 保洁 | D27: 001017 | E27: 后勤部 | F27: 保洁员 | G27: 后勤部 | H27: 后勤部 | I27: 在职 | J27: 45743 | M27: 2025年10月18日由行政部异动至后勤部 | O27: 群众 | R27: 15917839209 | S27: 女 | T27: 广东省鹤山市共和镇平汉村民委员会榜塘村75号 | V27: 440784198206232127 | W27: 已婚 | X27: 江门市江海区仁美新村35号之二503 | Y27: 高中 | Z27: / | AA27: 鹤山市职业技术学校 | AB27: 高中 | AC27: 直接 | AE27: 49822 | AF27: 36960 | AH27: 43 | AI27: 汉 | AL27: 45743 | AM27: 45742 | AN27: 月薪（没有伙食津贴） | AO27: 汉 | AP27: 直接 | AQ27: 45743 | AR27: 45742 | AS27: 月薪（没有伙食津贴） | AT27: 广东江门 | AU27: 2025 | AV27: 3 | AW27: 45835 | AX27: 0 | BL27: 在编 | BM27: 在编 | BN27: 在编 | BO27: 优化
A28: 37352 | B28: 胡翠敏 | C28: 保洁 | D28: 001017 | E28: 后勤部 | F28: 保洁员 | G28: 后勤部 | H28: 后勤部 | I28: 在职 | J28: 45848 | O28: 群众 | R28: 13326822341 | S28: 女 | T28: 广东省江门市江海区礼乐镇龙九如里50号 | V28: 440702198709221548 | W28: 未婚 | Y28: 初中 | Z28: / | AA28: 礼乐中学 | AB28: 初中 | AC28: 直接 | AE28: 49827 | AF28: 31014 | AH28: 38 | AI28: 汉 | AL28: 45848 | AM28: 45847 | AN28: 月薪（没有伙食津贴） | AO28: 汉 | AP28: 直接 | AQ28: 45848 | AR28: 45847 | AS28: 月薪（没有伙食津贴） | AT28: 广东江门 | AU28: 2025 | AV28: 3 | AW28: 45940 | AX28: 0 | BL28: 在编 | BM28: 在编 | BN28: 在编 | BO28: 在编 | BP28: 在编 | BQ28: 在编 | BR28: 优化
A29: 37576 | B29: 王时英 | C29: 保洁 | D29: 001017 | E29: 后勤部 | F29: 保洁员 | G29: 后勤部 | H29: 后勤部 | I29: 在职 | J29: 45868 | O29: 群众 | R29: 13536044786 | S29: 女 | T29: 广东省江门市蓬江区金怡居30幢之三401室 | V29: 610526198412056766 | W29: 已婚 | X29: 广东省江门市蓬江区金怡居30幢之三401室 | Y29: 初中 | Z29: / | AA29: 平路庙乡中学 | AB29: 初中 | AC29: 直接 | AE29: 52444 | AF29: 36772 | AH29: 41 | AI29: 汉 | AL29: 45868 | AM29: 45867 | AN29: 月薪（没有伙食津贴） | AO29: 汉 | AP29: 直接 | AQ29: 45868 | AR29: 45867 | AS29: 月薪（没有伙食津贴） | AT29: 陕西蒲城 | AU29: 2025 | AV29: 3 | AW29: 45960 | AX29: 0 | BL29: 在编 | BM29: 在编 | BN29: 在编 | BO29: 在编 | BP29: 在编 | BQ29: 在编 | BR29: 优化
A30: 38569 | B30: 伍金凤 | C30: 保洁 | D30: 001017 | E30: 后勤部 | F30: 保洁员 | G30: 后勤部 | H30: 后勤部 | I30: 在职 | J30: 46013 | O30: 群众 | R30: 13631843329 | S30: 女 | T30: 广东省江门市江海区外海东安里大街7号 | V30: 430481198410116708 | W30: 已婚 | X30: 广东省江门市江海区外海东安里大街7号 | Y30: 初中 | Z30: / | AA30: 红卫中学 | AB30: 初中 | AC30: 直接 | AE30: 50749 | AF30: 30966 | AH30: 41 | AI30: 汉 | AL30: 46013 | AM30: 46012 | AN30: 月薪（没有伙食津贴） | AO30: 汉 | AP30: 直接 | AQ30: 46013 | AR30: 46012 | AS30: 月薪（没有伙食津贴） | AT30: 广东江门 | AU30: 2025 | AV30: 3 | AW30: 46103 | AX30: 0 | BL30: 在编 | BM30: 在编 | BN30: 在编 | BO30: 在编 | BP30: 在编 | BQ30: 在编 | BR30: 优化
A31: 38570 | B31: 陆小娟 | C31: 保洁 | D31: 001017 | E31: 后勤部 | F31: 保洁员 | G31: 后勤部 | H31: 后勤部 | I31: 在职 | J31: 46013 | O31: 群众 | R31: 13631854353 | S31: 女 | T31: 广东省英德市沙口镇石坑村委会岭背组 | V31: 440782198001166848 | W31: 已婚 | X31: 广东省江门市江南街道南苑里77号 | Y31: 初中 | Z31: / | AA31: 桐井中学 | AB31: 初中 | AC31: 直接 | AE31: 50112 | AF31: 29236 | AH31: 46 | AI31: 汉 | AL31: 46013 | AM31: 46012 | AN31: 月薪（没有伙食津贴） | AO31: 汉 | AP31: 直接 | AQ31: 46013 | AR31: 46012 | AS31: 月薪（没有伙食津贴） | AT31: 广东江门 | AU31: 2025 | AV31: 3 | AW31: 46103 | AX31: 0 | BL31: 在编 | BM31: 在编 | BN31: 在编 | BO31: 在编 | BP31: 优化
A32: 1003 | B32: 冯秀萍 | C32: 综合物料库 | D32: 001017 | E32: 后勤部 | F32: 主管 | G32: 后勤部 | H32: 后勤部 | I32: 在职 | J32: 42430 | M32: 2023年3月由物管部调至工程项目部；2022年7月由物管部成品组主管调至工程项目部物管主管；2021年4月财务部调物管部；2020年4月由账务组长晋升为成品主管 | O32: 群众 | R32: 13555664920 | S32: 女 | T32: 广东省江门市新会区双水镇朱村新堂村51号 | V32: 440721197504083326 | W32: 已婚 | X32: 广东省江门市篷江区水南路61号503 | Y32: 中专 | Z32: 会计 | AA32: 新会成人中专 | AB32: 中专 | AC32: 直接 | AD32: 财务 | AE32: 46237 | AF32: 27492 | AH32: 50 | AI32: 汉 | AL32: 42430 | AN32: 月薪（没有伙食津贴） | AO32: 汉 | AQ32: 42430 | AS32: 月薪（没有伙食津贴） | AT32: 广东江门 | AU32: 2016 | AX32: 10 | BL32: 在编 | BM32: 在编 | BN32: 在编 | BO32: 在编 | BP32: 在编 | BQ32: 在编 | BR32: 在编 | BS32: 在编 | BT32: 在编 | BU32: 在编 | BV32: 在编 | BW32: 在编
A33: 21741 | B33: 林美凤 | C33: 综合物料库 | D33: 001017 | E33: 后勤部 | F33: 物管专员 | G33: 后勤部 | H33: 后勤部 | I33: 在职 | J33: 44024 | M33: 2025年9月16日由行政部异动至后勤部 | O33: 群众 | R33: 15019891811 | S33: 女 | T33: 广西靖西市龙临镇龙明村大明屯16号 | V33: 452626199709273827 | W33: 未婚 | X33: 广东省江门市江海区外海街道上石里十一巷3号 | Y33: 高中 | Z33: / | AA33: 靖西一中 | AB33: 高中 | AC33: 不对口 | AE33: 53143 | AF33: 32711 | AH33: 28 | AI33: 壮 | AL33: 44169 | AM33: 44166 | AN33: 月薪（没有伙食津贴） | AO33: 壮 | AP33: 直接 | AQ33: 44169 | AR33: 44166 | AS33: 月薪（没有伙食津贴） | AT33: 广西 | AU33: 2020 | AV33: 3 | AW33: 44257 | AX33: 5 | BL33: 在编 | BM33: 在编 | BN33: 在编 | BO33: 在编 | BP33: 在编 | BQ33: 在编 | BR33: 调岗
A34: 29099 | B34: 李小斌 | C34: 综合物料库 | D34: 001017 | E34: 后勤部 | F34: 物管专员 | G34: 后勤部 | H34: 生产部 | I34: 在职 | J34: 44754 | M34: 2024年11月调回宝士 生产二车间 2023年9月普工调为多能工；2023年2月1日由工程项目部调至生产部； 2023年2月1日由生产部2022年11月15日生产部调至工程项目部 | O34: 群众 | R34: 15009559052 | S34: 男 | T34: 山西省永济市城西街道小张村第四组 | V34: 142702198907220336 | W34: 未婚 | X34: 广东省江门市高新区东宁路101号万利公寓206 | Y34: 初中 | Z34: / | AA34: 永济市城西中学 | AB34: 初中 | AC34: 不对口 | AE34: 51359 | AF34: 35700 | AH34: 36 | AI34: 汉 | AL34: 44754 | AM34: 44753 | AN34: 月薪（没有伙食津贴） | AO34: 汉 | AP34: 直接 | AQ34: 44754 | AR34: 44753 | AS34: 月薪（没有伙食津贴） | AT34: 山西永济 | AU34: 2022 | AV34: 3 | AW34: 44846 | AX34: 3 | BL34: 在编 | BM34: 在编 | BN34: 在编 | BO34: 在编 | BP34: 在编 | BQ34: 调岗
A35: 34690 | B35: 朱家和 | C35: 综合物料库 | D35: 001017 | E35: 后勤部 | F35: 账务专员 | G35: 后勤部 | H35: 后勤部 | I35: 在职 | J35: 45510 | O35: 共青团员 | R35: 13354399472 | S35: 男 | T35: 广东省江门市新会区三江镇新马单马驷一村26号 | V35: 440782200110205316 | W35: 未婚 | X35: 广东省江门市新会区侨乐路18号716 | Y35: 大专 | Z35: 会计信息管理 | AA35: 广东财贸职业学院 | AB35: 大专 | AC35: 直接 | AE35: 48045 | AF35: 44489 | AH35: 24 | AI35: 汉 | AL35: 45510 | AM35: 45509 | AN35: 月薪（没有伙食津贴） | AO35: 汉 | AP35: 直接 | AQ35: 45510 | AR35: 45509 | AS35: 月薪（没有伙食津贴） | AT35: 广东江门 | AU35: 2024 | AV35: 3 | AW35: 45602 | AX35: 1 | BL35: 在编 | BM35: 在编 | BN35: 在编 | BO35: 在编 | BP35: 在编 | BQ35: 在编 | BR35: 在编 | BS35: 在编 | BT35: 在编 | BU35: 在编 | BV35: 在编 | BW35: 在编
A36: 4823 | B36: 曹艺强 | C36: 综合物料库 | D36: 001017 | E36: 后勤部 | F36: 材料监察 | G36: 后勤部 | H36: 生产部 | I36: 在职 | J36: 42958 | M36: 2023年8月物管部调至工程项目部；2022年12月入宝士；2021年12月1日入熹润；2022年4月由仓管员调至工程项目 物管专员；2022年6月调回仓管员 | O36: 共青团员 | R36: 13059257597 | S36: 男 | T36: 广东省台山市广海镇城北那章村15号 | V36: 440781199101185534 | W36: 未婚 | X36: 广东省江门市高新区东宁路101号万利公寓206 | Y36: 初中 | Z36: / | AA36: 振华中学 | AB36: 初中 | AC36: 不对口 | AE36: 46273 | AF36: 33256 | AH36: 35 | AI36: 汉 | AL36: 42958 | AM36: 43687 | AN36: 月薪（没有伙食津贴） | AO36: 汉 | AP36: 直接 | AQ36: 42958 | AR36: 43687 | AS36: 月薪（没有伙食津贴） | AT36: 广东台山 | AU36: 2017 | AV36: 3 | AW36: 43049 | AX36: 8 | BL36: 在编 | BM36: 在编 | BN36: 在编 | BO36: 调岗
A37: 22017 | B37: 梁美珍 | C37: 行政事务处 | D37: 001017 | E37: 后勤部 | F37: 主管 | G37: 后勤部 | H37: 后勤部 | I37: 在职 | J37: 44179 | M37: 2025年11月26日由行政部调整至后勤部；2025年9月晋升代主管 | O37: 群众 | R37: 15876267071 | S37: 女 | T37: 广东省江门市新会区古井镇慈溪第八村十五巷7号 | V37: 440782199706175028 | W37: 未婚 | X37: 广东省江门市江海区东宁路101号万利公寓301 | Y37: 大专 | Z37: 会展策划与管理 | AA37: 珠海城市职业技术学院 | AB37: 大专 | AC37: 直接 | AE37: 52429 | AF37: 35598 | AH37: 28 | AI37: 汉 | AL37: 44179 | AM37: 44178 | AN37: 月薪（没有伙食津贴） | AO37: 汉 | AP37: 直接 | AQ37: 44179 | AR37: 44178 | AS37: 月薪（没有伙食津贴） | AT37: 广东江门 | AU37: 2020 | AV37: 3 | AW37: 44269 | AX37: 5 | BL37: 在编 | BM37: 在编 | BN37: 在编 | BO37: 在编 | BP37: 在编 | BQ37: 在编 | BR37: 在编 | BS37: 在编 | BT37: 在编 | BU37: 在编 | BV37: 在编 | BW37: 在编
A38: 21740 | B38: 李彐苗 | C38: 行政事务处 | D38: 001017 | E38: 后勤部 | F38: 副主管 | G38: 后勤部 | H38: 后勤部 | I38: 在职 | J38: 44139 | M38: 2026.2.5行政异动至后勤部； 2022年6月24日由食宿专员调为代组长；2025.6.5由代组长转正为行政组长；2025年9月晋升代主管 | O38: 群众 | R38: 13855764701 | S38: 女 | T38: 安徽省萧县赵庄镇韩庄行政村韩庄自然村71号 | V38: 342222199512243242 | W38: 已婚 | X38: 广东省江门市江海区外海镇外海街道杏仁路亚奎巷13号 | Y38: 中专 | Z38: / | AA38: 滁州卫生学校 | AB38: 中专 | AC38: 不对口 | AE38: 53143 | AF38: 35057 | AH38: 30 | AI38: 汉 | AL38: 44169 | AM38: 44166 | AN38: 月薪（没有伙食津贴） | AO38: 汉 | AP38: 直接 | AQ38: 44169 | AR38: 44166 | AS38: 月薪（没有伙食津贴） | AT38: 安徽 | AU38: 2020 | AV38: 3 | AW38: 44257 | AX38: 5 | BL38: 在编 | BM38: 在编 | BN38: 在编 | BO38: 在编 | BP38: 在编 | BQ38: 在编 | BR38: 在编 | BS38: 在编 | BT38: 在编 | BU38: 在编 | BV38: 在编 | BW38: 在编
A39: 37594 | B39: 何绣敏 | C39: 行政事务处 | D39: 001017 | E39: 后勤部 | F39: 行政接待专员 | G39: 后勤部 | H39: 后勤部 | I39: 在职 | J39: 45874 | M39: 2025年12月10日行政部异动至后勤部；2025年9月16日由后勤部异动至行政部 | O39: 群众 | R39: 15975063278 | S39: 女 | T39: 广东省江门市江海区外海利亨街4巷4号 | V39: 440702200102221824 | W39: 未婚 | X39: 广东省江门市江海区海逸星宸星海轩3栋602 | Y39: 本科 | Z39: 英语 | AA39: 广州理工学院 | AB39: 二本 | AC39: 直接 | AD39: 英语 | AE39: 48045 | AF39: 36944 | AH39: 25 | AI39: 汉 | AL39: 45874 | AM39: 45873 | AN39: 月薪（没有伙食津贴） | AO39: 汉 | AP39: 直接 | AQ39: 45874 | AR39: 45873 | AS39: 月薪（没有伙食津贴） | AT39: 广东江门 | AU39: 2025 | AV39: 3 | AW39: 45966 | AX39: 0 | BL39: 在编 | BM39: 在编 | BN39: 在编 | BO39: 在编 | BP39: 优化
A40: 37604 | B40: 卢玉婵 | C40: 行政事务处 | D40: 001017 | E40: 后勤部 | F40: 文控专员 | G40: 后勤部 | H40: 后勤部 | I40: 在职 | J40: 45901 | M40: 2025年9月16日由后勤部异动至行政部 | O40: 群众 | R40: 13432206471 | S40: 女 | T40: 广东省江门市新会区睦洲镇石板沙下冲队45号 | V40: 44070520030529562X | W40: 未婚 | X40: 广东省江门市新会区睦洲镇新兴街西六巷8号 | Y40: 本科 | Z40: 历史学 | AA40: 岭南师范学院 | AB40: 二本 | AC40: 间接 | AE40: 47700 | AF40: 37770 | AH40: 22 | AI40: 汉 | AL40: 45901 | AM40: 45900 | AN40: 月薪（没有伙食津贴） | AO40: 汉 | AP40: 直接 | AQ40: 45901 | AR40: 45900 | AS40: 月薪（没有伙食津贴） | AT40: 广东江门 | AU40: 2025 | AV40: 3 | AW40: 45992 | AX40: 0 | BL40: 在编 | BM40: 在编 | BN40: 在编 | BO40: 在编 | BP40: 在编 | BQ40: 在编 | BR40: 在编 | BS40: 在编 | BT40: 在编 | BU40: 在编 | BV40: 在编 | BW40: 在编
...
